File: Vertiefung_Polymere/02_Data/PA.txt
Temp./C,Time/min,DSC/(mW/mg),Sensit./(uV/mW),Segment
    27.94100,0.0000e+000, 7.4320e-003,3.74183,1
    27.80812,5.5000e-002, 1.8013e-002,3.74183,1
    27.66700,    0.11000, 2.7026e-002,3.74182,1
    27.51571,    0.16500, 3.5446e-002,3.74182,1
    27.35288,    0.22000, 4.2929e-002,3.74181,1
    27.18041,    0.27500, 5.0921e-002,3.74181,1
    26.99553,    0.33000, 5.8361e-002,3.74180,1
    26.79782,    0.38500, 6.5475e-002,3.74179,1
    26.58935,    0.44000, 7.2404e-002,3.74178,1
    26.36718,    0.49500, 7.9577e-002,3.74177,1
    26.13147,    0.55000, 8.6871e-002,3.74175,1
    25.88294,    0.60500, 9.3533e-002,3.74174,1
    25.61953,    0.66000,     0.10125,3.74172,1
    25.33959,    0.71500,     0.10883,3.74170,1
    25.04518,    0.77000,     0.11669,3.74168,1
    24.73488,    0.82500,     0.12410,3.74166,1
    24.40688,    0.88000,     0.13285,3.74163,1
    24.06471,    0.93500,     0.14157,3.74161,1
    23.71171,    0.99000,     0.15036,3.74157,1
    23.34835,    1.04500,     0.15860,3.74154,1
    22.97782,    1.10000,     0.16607,3.74151,1
    22.59959,    1.15500,     0.17242,3.74147,1
    22.21329,    1.21000,     0.17874,3.74143,1
    21.81941,    1.26500,     0.18460,3.74138,1
    21.41918,    1.32000,     0.18960,3.74134,1
    21.00865,    1.37500,     0.19444,3.74129,1
    20.59047,    1.43000,     0.19934,3.74123,1
    20.16459,    1.48500,     0.20351,3.74118,1
    19.72971,    1.54000,     0.20820,3.74112,1
    19.28612,    1.59500,     0.21296,3.74105,1
    18.83512,    1.65000,     0.21725,3.74098,1
    18.37447,    1.70500,     0.22147,3.74091,1
    17.90676,    1.76000,     0.22619,3.74084,1
    17.42912,    1.81500,     0.22992,3.74076,1
    16.94365,    1.87000,     0.23445,3.74067,1
    16.45112,    1.92500,     0.23851,3.74058,1
    15.94859,    1.98000,     0.24264,3.74049,1
    15.43829,    2.03500,     0.24725,3.74039,1
    14.92100,    2.09000,     0.25113,3.74028,1
    14.39500,    2.14500,     0.25541,3.74017,1
     1.77247,    3.31167,     0.31124,3.73646,2
   -13.85435,    4.63167,     0.30392,3.72895,2
   -28.67324,    5.95167,     0.25875,3.71888,2
   -29.08129,    7.27167,-9.3245e-002,3.71856,2
   -24.75647,    8.59167,-6.0479e-002,3.72182,2
   -22.47312,    9.91167,-2.8419e-002,3.72344,2
   -21.25182,   11.23167,-1.1717e-002,3.72428,2
   -20.80163,   12.17167,-4.2931e-003,3.72459,3
   -20.48657,   12.22667, 3.0694e-002,3.72480,3
   -19.63123,   12.28167, 5.0177e-002,3.72537,3
   -18.33010,   12.33667,-4.5964e-002,3.72621,3
   -16.87392,   12.39167,    -0.19090,3.72713,3
   -15.43521,   12.44667,    -0.32488,3.72802,3
   -14.08036,   12.50167,    -0.42488,3.72882,3
   -12.81998,   12.55667,    -0.48849,3.72955,3
   -11.64248,   12.61167,    -0.52350,3.73021,3
   -10.53070,   12.66667,    -0.53838,3.73082,3
    -9.46823,   12.72167,    -0.54009,3.73138,3
    -8.43915,   12.77667,    -0.53474,3.73192,3
    -7.42977,   12.83167,    -0.52608,3.73243,3
    -6.42961,   12.88667,    -0.51682,3.73292,3
    -5.43246,   12.94167,    -0.50892,3.73340,3
    -4.43264,   12.99667,    -0.50275,3.73386,3
    -3.42574,   13.05167,    -0.49908,3.73432,3
    -2.41061,   13.10667,    -0.49718,3.73476,3
    -1.38716,   13.16167,    -0.49722,3.73520,3
    -0.35459,   13.21667,    -0.49925,3.73562,3
     0.68782,   13.27167,    -0.50258,3.73604,3
     1.73977,   13.32667,    -0.50668,3.73644,3
     2.80039,   13.38167,    -0.51154,3.73684,3
     3.86975,   13.43667,    -0.51715,3.73722,3
     4.94703,   13.49167,    -0.52295,3.73759,3
     6.03077,   13.54667,    -0.52883,3.73795,3
     7.12039,   13.60167,    -0.53491,3.73829,3
     8.21520,   13.65667,    -0.54105,3.73862,3
     9.31421,   13.71167,    -0.54673,3.73893,3
    10.41684,   13.76667,    -0.55245,3.73923,3
    11.52287,   13.82167,    -0.55811,3.73951,3
    12.63180,   13.87667,    -0.56338,3.73978,3
    13.74339,   13.93167,    -0.56829,3.74003,3
    14.85662,   13.98667,    -0.57303,3.74027,3
    15.97048,   14.04167,    -0.57772,3.74049,3
    17.08607,   14.09667,    -0.58200,3.74070,3
    18.20325,   14.15167,    -0.58632,3.74088,3
    19.32036,   14.20667,    -0.59038,3.74106,3
    20.43767,   14.26167,    -0.59438,3.74121,3
    21.55543,   14.31667,    -0.59814,3.74135,3
    22.67336,   14.37167,    -0.60186,3.74148,3
    23.79134,   14.42667,    -0.60550,3.74158,3
    24.90885,   14.48167,    -0.60923,3.74167,3
    26.02564,   14.53667,    -0.61308,3.74175,3
    27.14238,   14.59167,    -0.61640,3.74180,3
    28.25885,   14.64667,    -0.62001,3.74184,3
    29.37546,   14.70167,    -0.62314,3.74187,3
    30.49146,   14.75667,    -0.62724,3.74188,3
    31.60707,   14.81167,    -0.63096,3.74187,3
    32.72221,   14.86667,    -0.63495,3.74185,3
    33.83680,   14.92167,    -0.63882,3.74181,3
    34.95089,   14.97667,    -0.64290,3.74175,3
    36.06515,   15.03167,    -0.64703,3.74168,3
    37.17928,   15.08667,    -0.65195,3.74159,3
    38.29320,   15.14167,    -0.65681,3.74148,3
    39.40703,   15.19667,    -0.66204,3.74136,3
    40.52023,   15.25167,    -0.66774,3.74122,3
    41.63321,   15.30667,    -0.67373,3.74107,3
    42.74584,   15.36167,    -0.68031,3.74090,3
    43.85805,   15.41667,    -0.68755,3.74071,3
    44.97028,   15.47167,    -0.69553,3.74051,3
    46.08238,   15.52667,    -0.70428,3.74029,3
    47.19428,   15.58167,    -0.71422,3.74006,3
    48.30623,   15.63667,    -0.72492,3.73981,3
    49.41749,   15.69167,    -0.73687,3.73954,3
    50.52849,   15.74667,    -0.74917,3.73926,3
    51.63939,   15.80167,    -0.76112,3.73896,3
    52.75069,   15.85667,    -0.77182,3.73864,3
    53.86228,   15.91167,    -0.78035,3.73831,3
    54.97315,   15.96667,    -0.78746,3.73797,3
    56.08343,   16.02167,    -0.79351,3.73760,3
    57.19410,   16.07667,    -0.79958,3.73722,3
    58.30472,   16.13167,    -0.80610,3.73683,3
    59.41528,   16.18667,    -0.81283,3.73642,3
    60.52575,   16.24167,    -0.81881,3.73599,3
    61.63626,   16.29667,    -0.82317,3.73555,3
    62.74641,   16.35167,    -0.82610,3.73509,3
    63.85608,   16.40667,    -0.82732,3.73462,3
    64.96608,   16.46167,    -0.82750,3.73413,3
    66.07593,   16.51667,    -0.82711,3.73362,3
    67.18497,   16.57167,    -0.82673,3.73310,3
    68.29416,   16.62667,    -0.82662,3.73256,3
    69.40341,   16.68167,    -0.82682,3.73201,3
    70.51236,   16.73667,    -0.82742,3.73144,3
    71.62144,   16.79167,    -0.82824,3.73085,3
    72.73054,   16.84667,    -0.82943,3.73025,3
    73.83975,   16.90167,    -0.83044,3.72963,3
    74.94869,   16.95667,    -0.83213,3.72900,3
    76.05728,   17.01167,    -0.83365,3.72835,3
    77.16575,   17.06667,    -0.83563,3.72769,3
    78.27466,   17.12167,    -0.83793,3.72701,3
    79.38267,   17.17667,    -0.84024,3.72631,3
    80.49070,   17.23167,    -0.84265,3.72560,3
    81.59889,   17.28667,    -0.84553,3.72488,3
    82.70687,   17.34167,    -0.84800,3.72413,3
    83.81472,   17.39667,    -0.85079,3.72338,3
    84.92295,   17.45167,    -0.85419,3.72260,3
    86.03098,   17.50667,    -0.85727,3.72181,3
    87.13880,   17.56167,    -0.86073,3.72101,3
    88.24703,   17.61667,    -0.86392,3.72019,3
    89.35449,   17.67167,    -0.86718,3.71935,3
    90.46180,   17.72667,    -0.87084,3.71850,3
    91.56952,   17.78167,    -0.87405,3.71763,3
    92.67672,   17.83667,    -0.87739,3.71675,3
    93.78387,   17.89167,    -0.88069,3.71585,3
    94.89115,   17.94667,    -0.88381,3.71494,3
    95.99775,   18.00167,    -0.88712,3.71401,3
    97.10438,   18.05667,    -0.89030,3.71306,3
    98.21120,   18.11167,    -0.89331,3.71210,3
    99.31779,   18.16667,    -0.89648,3.71113,3
   100.42441,   18.22167,    -0.89944,3.71014,3
   101.53098,   18.27667,    -0.90247,3.70913,3
   102.63774,   18.33167,    -0.90561,3.70811,3
   103.74441,   18.38667,    -0.90855,3.70707,3
   104.85084,   18.44167,    -0.91135,3.70602,3
   105.95705,   18.49667,    -0.91461,3.70495,3
   107.06348,   18.55167,    -0.91724,3.70387,3
   108.17002,   18.60667,    -0.92051,3.70277,3
   109.27590,   18.66167,    -0.92298,3.70166,3
   110.38166,   18.71667,    -0.92569,3.70053,3
   111.48761,   18.77167,    -0.92854,3.69939,3
   112.59331,   18.82667,    -0.93113,3.69823,3
   113.69902,   18.88167,    -0.93369,3.69706,3
   114.80480,   18.93667,    -0.93598,3.69587,3
   115.91072,   18.99167,    -0.93884,3.69466,3
   117.01685,   19.04667,    -0.94133,3.69344,3
   118.12256,   19.10167,    -0.94364,3.69221,3
   119.22828,   19.15667,    -0.94604,3.69096,3
   120.33418,   19.21167,    -0.94838,3.68969,3
   121.43974,   19.26667,    -0.95046,3.68841,3
   122.54552,   19.32167,    -0.95275,3.68712,3
   123.65085,   19.37667,    -0.95450,3.68581,3
   124.75625,   19.43167,    -0.95643,3.68448,3
   125.86143,   19.48667,    -0.95829,3.68314,3
   126.96648,   19.54167,    -0.95981,3.68179,3
   128.07180,   19.59667,    -0.96186,3.68042,3
   129.17720,   19.65167,    -0.96358,3.67903,3
   130.28208,   19.70667,    -0.96537,3.67763,3
   131.38688,   19.76167,    -0.96746,3.67622,3
   132.49184,   19.81667,    -0.96907,3.67479,3
   133.59672,   19.87167,    -0.97071,3.67334,3
   134.70131,   19.92667,    -0.97229,3.67188,3
   135.80620,   19.98167,    -0.97438,3.67041,3
   136.91165,   20.03667,    -0.97595,3.66892,3
   138.01656,   20.09167,    -0.97771,3.66742,3
   139.12128,   20.14667,    -0.97942,3.66590,3
   140.22625,   20.20167,    -0.98126,3.66436,3
   141.33069,   20.25667,    -0.98275,3.66282,3
   142.43490,   20.31167,    -0.98433,3.66125,3
   143.53944,   20.36667,    -0.98581,3.65968,3
   144.64389,   20.42167,    -0.98733,3.65809,3
   145.74820,   20.47667,    -0.98924,3.65648,3
   146.85279,   20.53167,    -0.99078,3.65486,3
   147.95716,   20.58667,    -0.99230,3.65322,3
   149.06170,   20.64167,    -0.99399,3.65157,3
   150.16623,   20.69667,    -0.99577,3.64991,3
   151.27071,   20.75167,    -0.99710,3.64823,3
   152.37466,   20.80667,    -0.99856,3.64653,3
   153.47841,   20.86167,    -0.99971,3.64483,3
   154.58292,   20.91667,    -1.00091,3.64310,3
   155.68729,   20.97167,    -1.00186,3.64137,3
   156.79139,   21.02667,    -1.00278,3.63962,3
   157.89559,   21.08167,    -1.00389,3.63785,3
   158.99977,   21.13667,    -1.00481,3.63607,3
   160.10441,   21.19167,    -1.00643,3.63427,3
   161.20879,   21.24667,    -1.00911,3.63246,3
   162.31246,   21.30167,    -1.01322,3.63064,3
   163.41643,   21.35667,    -1.01956,3.62881,3
   164.52066,   21.41167,    -1.02897,3.62695,3
   165.62469,   21.46667,    -1.04223,3.62509,3
   166.72893,   21.52167,    -1.06062,3.62321,3
   167.83270,   21.57667,    -1.08354,3.62131,3
   168.93625,   21.63167,    -1.11211,3.61940,3
   170.03966,   21.68667,    -1.14563,3.61748,3
   171.14346,   21.74167,    -1.18530,3.61555,3
   172.24756,   21.79667,    -1.23370,3.61360,3
   173.35100,   21.85167,    -1.29067,3.61163,3
   174.45426,   21.90667,    -1.35679,3.60965,3
   175.55721,   21.96167,    -1.43240,3.60766,3
   176.65985,   22.01667,    -1.52170,3.60566,3
   177.76254,   22.07167,    -1.63003,3.60364,3
   178.86474,   22.12667,    -1.75114,3.60161,3
   179.96748,   22.18167,    -1.84506,3.59956,3
   181.07043,   22.23667,    -1.92147,3.59750,3
   182.17357,   22.29167,    -1.98267,3.59542,3
   183.27728,   22.34667,    -2.03388,3.59333,3
   184.38102,   22.40167,    -2.08655,3.59123,3
   185.48479,   22.45667,    -2.18983,3.58911,3
   186.58813,   22.51167,    -2.28759,3.58698,3
   187.69185,   22.56667,    -2.24307,3.58484,3
   188.79675,   22.62167,    -2.03678,3.58267,3
   189.90207,   22.67667,    -1.79094,3.58050,3
   191.00787,   22.73167,    -1.58271,3.57831,3
   192.11367,   22.78667,    -1.42385,3.57610,3
   193.21892,   22.84167,    -1.30782,3.57389,3
   194.32393,   22.89667,    -1.22327,3.57166,3
   195.42843,   22.95167,    -1.16326,3.56941,3
   196.53220,   23.00667,    -1.12091,3.56716,3
   197.63608,   23.06167,    -1.09102,3.56489,3
   198.73990,   23.11667,    -1.07011,3.56261,3
   199.84367,   23.17167,    -1.05576,3.56031,3
   200.94674,   23.22667,    -1.04603,3.55801,3
   202.04949,   23.28167,    -1.03952,3.55569,3
   203.15261,   23.33667,    -1.03533,3.55335,3
   204.25513,   23.39167,    -1.03294,3.55101,3
   205.35769,   23.44667,    -1.03160,3.54865,3
   206.46041,   23.50167,    -1.03056,3.54627,3
   207.56349,   23.55667,    -1.03056,3.54389,3
   208.66713,   23.61167,    -1.03095,3.54148,3
   209.77082,   23.66667,    -1.03163,3.53907,3
   210.87449,   23.72167,    -1.03265,3.53664,3
   211.97795,   23.77667,    -1.03359,3.53420,3
   213.08116,   23.83167,    -1.03486,3.53175,3
   214.18436,   23.88667,    -1.03603,3.52928,3
   215.28743,   23.94167,    -1.03704,3.52680,3
   216.39046,   23.99667,    -1.03817,3.52431,3
   217.49364,   24.05167,    -1.03962,3.52180,3
   218.59706,   24.10667,    -1.04049,3.51928,3
   219.70003,   24.16167,    -1.04177,3.51675,3
   220.80280,   24.21667,    -1.04288,3.51421,3
   221.90543,   24.27167,    -1.04420,3.51165,3
   223.00836,   24.32667,    -1.04537,3.50909,3
   224.11154,   24.38167,    -1.04665,3.50650,3
   225.21472,   24.43667,    -1.04790,3.50391,3
   226.31785,   24.49167,    -1.04926,3.50130,3
   227.42087,   24.54667,    -1.05041,3.49868,3
   228.52413,   24.60167,    -1.05161,3.49604,3
   229.62759,   24.65667,    -1.05297,3.49340,3
   230.73090,   24.71167,    -1.05402,3.49074,3
   231.83392,   24.76667,    -1.05524,3.48807,3
   232.93654,   24.82167,    -1.05657,3.48538,3
   234.03933,   24.87667,    -1.05760,3.48269,3
   235.14249,   24.93167,    -1.05883,3.47998,3
   236.24595,   24.98667,    -1.06002,3.47726,3
   237.34903,   25.04167,    -1.06116,3.47452,3
   238.45180,   25.09667,    -1.06214,3.47178,3
   239.55480,   25.15167,    -1.06320,3.46902,3
   240.65771,   25.20667,    -1.06437,3.46625,3
   241.76089,   25.26167,    -1.06542,3.46346,3
   242.86426,   25.31667,    -1.06643,3.46067,3
   243.96752,   25.37167,    -1.06739,3.45786,3
   245.07033,   25.42667,    -1.06850,3.45504,3
   246.17357,   25.48167,    -1.06946,3.45221,3
   247.27689,   25.53667,    -1.07042,3.44936,3
   248.38038,   25.59167,    -1.07148,3.44650,3
   249.48347,   25.64667,    -1.07250,3.44363,3
   250.58634,   25.70167,    -1.07363,3.44075,3
   251.68957,   25.75667,    -1.07462,3.43786,3
   252.79249,   25.81167,    -1.07554,3.43495,3
   253.89573,   25.86667,    -1.07638,3.43204,3
   254.99627,   25.92167,    -1.07742,3.42911,4
   256.08241,   25.97667,    -1.08028,3.42622,4
   256.92335,   26.03167,    -1.07611,3.42397,4
   257.15759,   26.08667,    -0.98095,3.42334,4
   256.54118,   26.14167,    -0.72219,3.42499,4
   255.13994,   26.19667,    -0.29826,3.42873,4
   253.34553,   26.25167,     0.18847,3.43349,4
   251.47877,   26.30667,     0.60040,3.43841,4
   249.66677,   26.36167,     0.88887,3.44316,4
   247.94829,   26.41667,     1.07205,3.44762,4
   246.33359,   26.47167,     1.17216,3.45179,4
   244.81918,   26.52667,     1.21136,3.45568,4
   243.39418,   26.58167,     1.21534,3.45932,4
   242.04135,   26.63667,     1.19271,3.46275,4
   240.75141,   26.69167,     1.15909,3.46601,4
   239.51535,   26.74667,     1.12114,3.46912,4
   238.31988,   26.80167,     1.07925,3.47210,4
   237.15377,   26.85667,     1.04159,3.47501,4
   236.01123,   26.91167,     1.00863,3.47784,4
   234.88241,   26.96667,     0.97902,3.48062,4
   233.76500,   27.02167,     0.95629,3.48336,4
   232.65377,   27.07667,     0.93809,3.48607,4
   231.54535,   27.13167,     0.92314,3.48877,4
   230.43782,   27.18667,     0.91323,3.49145,4
   229.33165,   27.24167,     0.90629,3.49411,4
   228.22094,   27.29667,     0.90130,3.49677,4
   227.10888,   27.35167,     0.89887,3.49942,4
   225.99688,   27.40667,     0.89748,3.50206,4
   224.88024,   27.46167,     0.89656,3.50470,4
   223.76247,   27.51667,     0.89751,3.50732,4
   222.64565,   27.57167,     0.89779,3.50993,4
   221.52518,   27.62667,     0.89777,3.51254,4
   220.40359,   27.68167,     0.89946,3.51513,4
   219.28300,   27.73667,     0.90076,3.51771,4
   218.16212,   27.79167,     0.90101,3.52028,4
   217.04270,   27.84667,     0.90182,3.52283,4
   215.92647,   27.90167,     0.90123,3.52536,4
   214.81012,   27.95667,     0.90021,3.52788,4
   213.69583,   28.01167,     0.89997,3.53037,4
   212.58382,   28.06667,     0.89843,3.53285,4
   211.47283,   28.12167,     0.89691,3.53532,4
   210.36264,   28.17667,     0.89604,3.53777,4
   209.25271,   28.23167,     0.89436,3.54020,4
   208.14112,   28.28667,     0.89368,3.54263,4
   207.02959,   28.34167,     0.89386,3.54504,4
   205.91729,   28.39667,     0.89318,3.54744,4
   204.80553,   28.45167,     0.89332,3.54983,4
   203.69506,   28.50667,     0.89336,3.55220,4
   202.58471,   28.56167,     0.89246,3.55455,4
   201.47570,   28.61667,     0.89178,3.55689,4
   200.37006,   28.67167,     0.89098,3.55921,4
   199.26494,   28.72667,     0.88920,3.56152,4
   198.15841,   28.78167,     0.88823,3.56381,4
   197.05294,   28.83667,     0.88811,3.56609,4
   195.94724,   28.89167,     0.88677,3.56836,4
   194.84241,   28.94667,     0.88648,3.57060,4
   193.73806,   29.00167,     0.88581,3.57284,4
   192.63347,   29.05667,     0.88446,3.57506,4
   191.53041,   29.11167,     0.88429,3.57727,4
   190.42841,   29.16667,     0.88321,3.57946,4
   189.32153,   29.22167,     0.88205,3.58164,4
   188.21430,   29.27667,     0.88317,3.58382,4
   187.10947,   29.33167,     0.88344,3.58597,4
   186.00606,   29.38667,     0.88235,3.58811,4
   184.90188,   29.44167,     0.88193,3.59023,4
   183.79647,   29.49667,     0.88140,3.59235,4
   182.69771,   29.55167,     0.88065,3.59443,4
   181.60047,   29.60667,     0.87865,3.59650,4
   180.49612,   29.66167,     0.87651,3.59857,4
   179.38676,   29.71667,     0.87756,3.60064,4
   178.28106,   29.77167,     0.87970,3.60268,4
   177.18200,   29.82667,     0.87872,3.60470,4
   176.08047,   29.88167,     0.87592,3.60671,4
   174.97482,   29.93667,     0.87587,3.60872,4
   173.87188,   29.99167,     0.87626,3.61070,4
   172.77617,   30.04667,     0.87555,3.61266,4
   171.68112,   30.10167,     0.87284,3.61460,4
   170.57688,   30.15667,     0.87085,3.61654,4
   169.47518,   30.21167,     0.87189,3.61847,4
   168.38159,   30.26667,     0.87181,3.62037,4
   167.28718,   30.32167,     0.86836,3.62225,4
   166.18659,   30.37667,     0.86700,3.62413,4
   165.08429,   30.43167,     0.86776,3.62600,4
   163.98182,   30.48667,     0.86767,3.62786,4
   162.87629,   30.54167,     0.86833,3.62971,4
   161.77071,   30.59667,     0.86944,3.63154,4
   160.67035,   30.65167,     0.86919,3.63335,4
   159.57235,   30.70667,     0.86760,3.63514,4
   158.46976,   30.76167,     0.86576,3.63693,4
   157.36777,   30.81667,     0.86607,3.63870,4
   156.27188,   30.87167,     0.86567,3.64044,4
   155.17229,   30.92667,     0.86332,3.64218,4
   154.06935,   30.98167,     0.86274,3.64391,4
   152.96988,   31.03667,     0.86505,3.64562,4
   151.87229,   31.09167,     0.87084,3.64731,4
   150.76912,   31.14667,     0.89063,3.64899,4
   149.66853,   31.20167,     0.94463,3.65066,4
   148.57312,   31.25667,     1.06300,3.65230,4
   147.47912,   31.31167,     1.28454,3.65393,4
   146.38641,   31.36667,     1.60339,3.65554,4
   145.29371,   31.42167,     1.96919,3.65714,4
   144.19524,   31.47667,     2.25272,3.65873,4
   143.09547,   31.53167,     2.42091,3.66031,4
   141.99735,   31.58667,     2.46605,3.66187,4
   140.89641,   31.64167,     2.42820,3.66343,4
   139.79370,   31.69667,     2.31508,3.66497,4
   138.69223,   31.75167,     2.13871,3.66649,4
   137.58882,   31.80667,     1.92961,3.66800,4
   136.48600,   31.86167,     1.71843,3.66949,4
   135.38853,   31.91667,     1.53314,3.67097,4
   134.28776,   31.97167,     1.38911,3.67243,4
   133.18859,   32.02667,     1.27474,3.67388,4
   132.09206,   32.08167,     1.18841,3.67530,4
   130.99159,   32.13667,     1.12376,3.67672,4
   129.89035,   32.19167,     1.07592,3.67813,4
   128.79406,   32.24667,     1.03818,3.67951,4
   127.69706,   32.30167,     1.00797,3.68088,4
   126.60100,   32.35667,     0.98474,3.68223,4
   125.50529,   32.41167,     0.96484,3.68357,4
   124.40253,   32.46667,     0.94957,3.68491,4
   123.29865,   32.52167,     0.93906,3.68622,4
   122.20153,   32.57667,     0.92801,3.68752,4
   121.10518,   32.63167,     0.91828,3.68880,4
   120.00847,   32.68667,     0.90912,3.69006,4
   118.91406,   32.74166,     0.90042,3.69131,4
   117.81329,   32.79667,     0.89353,3.69255,4
   116.71129,   32.85167,     0.88809,3.69378,4
   115.61576,   32.90667,     0.88167,3.69498,4
   114.51976,   32.96167,     0.87509,3.69617,4
   113.42412,   33.01667,     0.86837,3.69735,4
   112.32965,   33.07167,     0.86249,3.69851,4
   111.23176,   33.12667,     0.85663,3.69965,4
   110.13182,   33.18167,     0.85146,3.70079,4
   109.03641,   33.23667,     0.84663,3.70190,4
   107.93800,   33.29167,     0.84054,3.70300,4
   106.84018,   33.34667,     0.83640,3.70409,4
   105.74459,   33.40167,     0.83138,3.70516,4
   104.64418,   33.45667,     0.82581,3.70622,4
   103.54288,   33.51167,     0.82325,3.70726,4
   102.44824,   33.56667,     0.81948,3.70829,4
   101.34935,   33.62167,     0.81417,3.70930,4
   100.25082,   33.67667,     0.81146,3.71030,4
    99.15806,   33.73167,     0.80814,3.71127,4
    98.06171,   33.78667,     0.80431,3.71224,4
    96.96359,   33.84167,     0.80217,3.71319,4
    95.87094,   33.89667,     0.79989,3.71412,4
    94.77171,   33.95167,     0.79630,3.71504,4
    93.67235,   34.00667,     0.79534,3.71594,4
    92.57688,   34.06167,     0.79330,3.71683,4
    91.47941,   34.11666,     0.78938,3.71770,4
    90.38076,   34.17167,     0.78689,3.71856,4
    89.28624,   34.22667,     0.78333,3.71940,4
    88.18829,   34.28167,     0.77860,3.72023,4
    87.09035,   34.33667,     0.77580,3.72104,4
    85.99594,   34.39167,     0.77098,3.72184,4
    84.89859,   34.44667,     0.76596,3.72262,4
    83.80447,   34.50167,     0.76105,3.72338,4
    82.71035,   34.55667,     0.75473,3.72413,4
    81.61547,   34.61167,     0.74931,3.72487,4
    80.52041,   34.66667,     0.74352,3.72558,4
    79.42241,   34.72167,     0.73830,3.72629,4
    78.32812,   34.77667,     0.73306,3.72698,4
    77.23229,   34.83167,     0.72642,3.72765,4
    76.14029,   34.88667,     0.72093,3.72830,4
    75.04818,   34.94167,     0.71320,3.72894,4
    73.95476,   34.99667,     0.70704,3.72957,4
    72.86535,   35.05167,     0.68449,3.73018,4
    71.77377,   35.10667,     0.66976,3.73077,4
    70.68665,   35.16167,     0.67074,3.73135,4
    69.59788,   35.21667,     0.66732,3.73191,4
    68.51124,   35.27167,     0.66426,3.73245,4
    67.42588,   35.32667,     0.65918,3.73298,4
    66.33900,   35.38167,     0.65412,3.73350,4
    65.25488,   35.43667,     0.64946,3.73400,4
    64.16806,   35.49166,     0.64369,3.73448,4
    63.08106,   35.54667,     0.63930,3.73495,4
    61.99294,   35.60167,     0.63414,3.73540,4
    60.90294,   35.65667,     0.62965,3.73584,4
    59.81394,   35.71167,     0.62506,3.73627,4
    58.72147,   35.76667,     0.62005,3.73668,4
    57.62941,   35.82167,     0.61613,3.73707,4
    56.53647,   35.87667,     0.61108,3.73745,4
    55.44188,   35.93167,     0.60710,3.73781,4
    54.34771,   35.98667,     0.60290,3.73816,4
    53.25194,   36.04167,     0.59801,3.73850,4
    52.15724,   36.09667,     0.59381,3.73881,4
    51.05982,   36.15167,     0.58825,3.73912,4
    49.96447,   36.20667,     0.58468,3.73940,4
    48.86665,   36.26167,     0.57884,3.73967,4
    47.76847,   36.31667,     0.57470,3.73993,4
    46.67088,   36.37167,     0.56948,3.74017,4
    45.57276,   36.42667,     0.56469,3.74039,4
    44.47553,   36.48167,     0.55972,3.74060,4
    43.37529,   36.53667,     0.55422,3.74079,4
    42.27835,   36.59167,     0.54989,3.74097,4
    41.17929,   36.64667,     0.54436,3.74113,4
    40.08065,   36.70167,     0.53926,3.74128,4
    38.98218,   36.75667,     0.53384,3.74141,4
    37.88382,   36.81167,     0.52842,3.74152,4
    36.78600,   36.86666,     0.52365,3.74162,4
    35.68600,   36.92167,     0.51805,3.74170,4
    34.58865,   36.97667,     0.51357,3.74177,4
    33.49006,   37.03167,     0.50804,3.74182,4
    32.39147,   37.08667,     0.50373,3.74185,4
    31.29282,   37.14167,     0.49845,3.74187,4
    30.19388,   37.19667,     0.49412,3.74188,4
    29.09529,   37.25167,     0.48960,3.74186,4
    27.99553,   37.30667,     0.48521,3.74184,4
    26.89771,   37.36167,     0.48106,3.74179,4
    25.79794,   37.41667,     0.47682,3.74173,4
    24.69965,   37.47167,     0.47336,3.74166,4
    23.60018,   37.52667,     0.46903,3.74156,4
    22.50194,   37.58167,     0.46602,3.74146,4
    21.40388,   37.63667,     0.46218,3.74133,4
    20.30418,   37.69167,     0.45893,3.74119,4
    19.20535,   37.74667,     0.45556,3.74104,4
    18.10518,   37.80167,     0.45264,3.74087,4
    17.00665,   37.85667,     0.44972,3.74068,4
    15.90541,   37.91167,     0.44634,3.74048,4
    14.80618,   37.96667,     0.44403,3.74026,4
    13.70535,   38.02167,     0.44086,3.74003,4
    12.60518,   38.07667,     0.43805,3.73977,4
    11.50582,   38.13167,     0.43548,3.73951,4
    10.40600,   38.18667,     0.43282,3.73923,4
     9.30635,   38.24166,     0.42973,3.73893,4
     8.20565,   38.29667,     0.42727,3.73861,4
     7.10576,   38.35167,     0.42438,3.73828,4
     6.00335,   38.40667,     0.42189,3.73794,4
     4.90265,   38.46167,     0.41948,3.73757,4
     3.80100,   38.51667,     0.41678,3.73720,4
     2.69900,   38.57167,     0.41445,3.73680,4
     1.59394,   38.62667,     0.41157,3.73639,4
     0.48912,   38.68167,     0.41018,3.73596,4
    -0.61624,   38.73667,     0.40749,3.73552,4
    -1.72182,   38.79167,     0.40608,3.73506,4
    -2.82765,   38.84667,     0.40317,3.73458,4
    -3.93176,   38.90167,     0.40122,3.73409,4
    -5.03435,   38.95667,     0.39849,3.73358,4
    -6.13671,   39.01167,     0.39558,3.73306,4
    -7.23565,   39.06667,     0.39309,3.73252,4
    -8.33600,   39.12167,     0.39002,3.73197,4
    -9.43182,   39.17667,     0.38783,3.73140,4
   -10.52282,   39.23167,     0.38488,3.73082,4
   -11.60271,   39.28667,     0.38248,3.73023,4
   -12.66700,   39.34167,     0.37870,3.72964,4
   -13.71518,   39.39667,     0.37383,3.72904,4
   -14.74712,   39.45167,     0.36761,3.72843,4
   -15.76335,   39.50667,     0.36072,3.72782,4
   -16.76235,   39.56167,     0.35334,3.72720,4
   -17.74712,   39.61666,     0.34608,3.72659,4
   -19.88860,   39.74833,     0.33639,3.72520,5
   -20.40171,   41.06833,-1.5820e-002,3.72486,5
   -20.09129,   42.38833, 3.7238e-003,3.72506,5
   -19.98341,   43.70833, 4.6124e-003,3.72514,5
   -20.00441,   45.02833, 5.6336e-003,3.72512,5
   -20.01782,   46.34833, 5.8779e-003,3.72511,5
   -20.01865,   47.66833, 6.4100e-003,3.72511,5
   -20.01159,   48.98833, 4.3240e-003,3.72512,5
   -20.00410,   49.69750, 5.6740e-003,3.72512,6
   -19.62874,   49.75250, 6.6112e-002,3.72537,6
   -18.70279,   49.80750, 7.7594e-002,3.72597,6
   -17.37418,   49.86250,-4.7863e-002,3.72682,6
   -15.92659,   49.91750,    -0.20758,3.72772,6
   -14.51384,   49.97250,    -0.33397,3.72857,6
   -13.19087,   50.02750,    -0.41052,3.72934,6
   -11.96197,   50.08250,    -0.44474,3.73003,6
   -10.81336,   50.13750,    -0.45158,3.73067,6
    -9.72902,   50.19250,    -0.44274,3.73125,6
    -8.69062,   50.24750,    -0.42682,3.73179,6
    -7.68130,   50.30250,    -0.40973,3.73230,6
    -6.68872,   50.35750,    -0.39414,3.73279,6
    -5.70369,   50.41250,    -0.38187,3.73327,6
    -4.72008,   50.46750,    -0.37278,3.73373,6
    -3.73270,   50.52250,    -0.36753,3.73418,6
    -2.73807,   50.57750,    -0.36537,3.73462,6
    -1.73518,   50.63250,    -0.36504,3.73505,6
    -0.72318,   50.68750,    -0.36700,3.73547,6
     0.29841,   50.74250,    -0.37049,3.73589,6
     1.32984,   50.79750,    -0.37463,3.73629,6
     2.37159,   50.85250,    -0.37961,3.73668,6
     3.42259,   50.90750,    -0.38495,3.73706,6
     4.48190,   50.96250,    -0.39049,3.73743,6
     5.54892,   51.01750,    -0.39635,3.73779,6
     6.62282,   51.07250,    -0.40185,3.73813,6
     7.70295,   51.12750,    -0.40750,3.73846,6
     8.78821,   51.18250,    -0.41249,3.73878,6
     9.87802,   51.23750,    -0.41769,3.73908,6
    10.97230,   51.29250,    -0.42255,3.73937,6
    12.06990,   51.34750,    -0.42736,3.73965,6
    13.17034,   51.40250,    -0.43177,3.73991,6
    14.27290,   51.45750,    -0.43569,3.74015,6
    15.37759,   51.51250,    -0.44011,3.74038,6
    16.48379,   51.56750,    -0.44401,3.74059,6
    17.59095,   51.62250,    -0.44747,3.74078,6
    18.69920,   51.67750,    -0.45129,3.74096,6
    19.80889,   51.73250,    -0.45456,3.74113,6
    20.91854,   51.78750,    -0.45825,3.74127,6
    22.02821,   51.84250,    -0.46142,3.74141,6
    23.13841,   51.89750,    -0.46494,3.74152,6
    24.24836,   51.95250,    -0.46841,3.74162,6
    25.35889,   52.00750,    -0.47128,3.74170,6
    26.46913,   52.06250,    -0.47499,3.74177,6
    27.57880,   52.11750,    -0.47842,3.74182,6
    28.68911,   52.17250,    -0.48202,3.74186,6
    29.79911,   52.22750,    -0.48537,3.74187,6
    30.90849,   52.28250,    -0.48925,3.74188,6
    32.01749,   52.33750,    -0.49307,3.74186,6
    33.12602,   52.39250,    -0.49680,3.74183,6
    34.23416,   52.44750,    -0.50089,3.74179,6
    35.34259,   52.50250,    -0.50517,3.74173,6
    36.45079,   52.55750,    -0.50998,3.74165,6
    37.55897,   52.61250,    -0.51479,3.74155,6
    38.66716,   52.66750,    -0.51997,3.74144,6
    39.77538,   52.72250,    -0.52546,3.74132,6
    40.88379,   52.77750,    -0.53084,3.74117,6
    41.99205,   52.83250,    -0.53692,3.74102,6
    43.10023,   52.88750,    -0.54252,3.74084,6
    44.20795,   52.94250,    -0.54841,3.74065,6
    45.31562,   52.99750,    -0.55422,3.74044,6
    46.42338,   53.05250,    -0.55979,3.74022,6
    47.53056,   53.10750,    -0.56552,3.73998,6
    48.63784,   53.16250,    -0.57090,3.73973,6
    49.74556,   53.21750,    -0.57641,3.73946,6
    50.85321,   53.27250,    -0.58191,3.73917,6
    51.96034,   53.32750,    -0.58713,3.73887,6
    53.06756,   53.38250,    -0.59223,3.73855,6
    54.17534,   53.43750,    -0.59713,3.73822,6
    55.28269,   53.49250,    -0.60205,3.73787,6
    56.38952,   53.54750,    -0.60704,3.73750,6
    57.49654,   53.60250,    -0.61194,3.73712,6
    58.60354,   53.65750,    -0.61661,3.73672,6
    59.71126,   53.71250,    -0.62143,3.73631,6
    60.81882,   53.76750,    -0.62596,3.73588,6
    61.92620,   53.82250,    -0.63090,3.73543,6
    63.03348,   53.87750,    -0.63552,3.73497,6
    64.14031,   53.93250,    -0.64021,3.73449,6
    65.24720,   53.98750,    -0.64492,3.73400,6
    66.35387,   54.04250,    -0.64941,3.73349,6
    67.46079,   54.09750,    -0.65376,3.73297,6
    68.56733,   54.15250,    -0.65853,3.73243,6
    69.67354,   54.20750,    -0.66274,3.73187,6
    70.77967,   54.26250,    -0.66735,3.73130,6
    71.88620,   54.31750,    -0.67176,3.73071,6
    72.99310,   54.37250,    -0.67642,3.73011,6
    74.09967,   54.42750,    -0.68116,3.72949,6
    75.20608,   54.48250,    -0.68564,3.72885,6
    76.31267,   54.53750,    -0.69015,3.72820,6
    77.41952,   54.59250,    -0.69475,3.72754,6
    78.52638,   54.64750,    -0.69920,3.72685,6
    79.63252,   54.70250,    -0.70393,3.72616,6
    80.73856,   54.75750,    -0.70870,3.72544,6
    81.84423,   54.81250,    -0.71313,3.72471,6
    82.94989,   54.86750,    -0.71748,3.72397,6
    84.05570,   54.92250,    -0.72206,3.72321,6
    85.16180,   54.97750,    -0.72669,3.72243,6
    86.26803,   55.03250,    -0.73132,3.72164,6
    87.37466,   55.08750,    -0.73578,3.72083,6
    88.48074,   55.14250,    -0.74066,3.72001,6
    89.58677,   55.19750,    -0.74531,3.71917,6
    90.69284,   55.25250,    -0.75001,3.71832,6
    91.79884,   55.30750,    -0.75452,3.71745,6
    92.90454,   55.36250,    -0.75923,3.71657,6
    94.01041,   55.41750,    -0.76391,3.71567,6
    95.11661,   55.47250,    -0.76834,3.71475,6
    96.22216,   55.52750,    -0.77319,3.71382,6
    97.32780,   55.58250,    -0.77775,3.71287,6
    98.43321,   55.63750,    -0.78260,3.71191,6
    99.53839,   55.69250,    -0.78734,3.71093,6
   100.64390,   55.74750,    -0.79211,3.70994,6
   101.74882,   55.80250,    -0.79677,3.70893,6
   102.85400,   55.85750,    -0.80180,3.70791,6
   103.95913,   55.91250,    -0.80662,3.70687,6
   105.06420,   55.96750,    -0.81149,3.70582,6
   106.16938,   56.02250,    -0.81657,3.70475,6
   107.27438,   56.07750,    -0.82174,3.70366,6
   108.37995,   56.13250,    -0.82684,3.70256,6
   109.48528,   56.18750,    -0.83188,3.70145,6
   110.59021,   56.24250,    -0.83707,3.70032,6
   111.69528,   56.29750,    -0.84274,3.69917,6
   112.80023,   56.35250,    -0.84805,3.69801,6
   113.90490,   56.40750,    -0.85367,3.69683,6
   115.00984,   56.46250,    -0.85928,3.69564,6
   116.11493,   56.51750,    -0.86527,3.69444,6
   117.22000,   56.57250,    -0.87100,3.69322,6
   118.32518,   56.62750,    -0.87681,3.69198,6
   119.43008,   56.68250,    -0.88309,3.69073,6
   120.53485,   56.73750,    -0.88884,3.68946,6
   121.63952,   56.79250,    -0.89448,3.68818,6
   122.74438,   56.84750,    -0.90012,3.68688,6
   123.84885,   56.90250,    -0.90608,3.68557,6
   124.95313,   56.95750,    -0.91196,3.68424,6
   126.05739,   57.01250,    -0.91793,3.68290,6
   127.16175,   57.06750,    -0.92377,3.68154,6
   128.26662,   57.12250,    -0.93020,3.68017,6
   129.37128,   57.17750,    -0.93655,3.67879,6
   130.47572,   57.23250,    -0.94310,3.67738,6
   131.58061,   57.28750,    -0.94999,3.67597,6
   132.68518,   57.34250,    -0.95690,3.67453,6
   133.78954,   57.39750,    -0.96393,3.67309,6
   134.89416,   57.45250,    -0.97116,3.67163,6
   135.99800,   57.50750,    -0.97813,3.67015,6
   137.10134,   57.56250,    -0.98550,3.66866,6
   138.20523,   57.61750,    -0.99302,3.66716,6
   139.30916,   57.67250,    -1.00017,3.66564,6
   140.41305,   57.72750,    -1.00775,3.66410,6
   141.51728,   57.78250,    -1.01546,3.66255,6
   142.62179,   57.83750,    -1.02321,3.66099,6
   143.72595,   57.89250,    -1.03116,3.65941,6
   144.82992,   57.94750,    -1.03875,3.65782,6
   145.93418,   58.00250,    -1.04692,3.65621,6
   147.03825,   58.05750,    -1.05501,3.65458,6
   148.14208,   58.11250,    -1.06355,3.65295,6
   149.24600,   58.16750,    -1.07264,3.65130,6
   150.34987,   58.22250,    -1.08177,3.64963,6
   151.45412,   58.27750,    -1.09091,3.64795,6
   152.55854,   58.33250,    -1.09988,3.64625,6
   153.66244,   58.38750,    -1.10850,3.64454,6
   154.76625,   58.44250,    -1.11661,3.64282,6
   155.87016,   58.49750,    -1.12470,3.64108,6
   156.97362,   58.55250,    -1.13214,3.63933,6
   158.07684,   58.60750,    -1.13973,3.63756,6
   159.18105,   58.66250,    -1.14705,3.63578,6
   160.28572,   58.71750,    -1.15449,3.63398,6
   161.38990,   58.77250,    -1.16225,3.63217,6
   162.49312,   58.82750,    -1.17104,3.63034,6
   163.59648,   58.88250,    -1.18074,3.62850,6
   164.70016,   58.93750,    -1.19204,3.62665,6
   165.80356,   58.99250,    -1.20587,3.62478,6
   166.90698,   59.04750,    -1.22397,3.62290,6
   168.01067,   59.10250,    -1.25024,3.62101,6
   169.11425,   59.15750,    -1.29622,3.61910,6
   170.21759,   59.21250,    -1.35857,3.61717,6
   171.32080,   59.26750,    -1.40993,3.61523,6
   172.42385,   59.32250,    -1.45650,3.61328,6
   173.52715,   59.37750,    -1.50746,3.61132,6
   174.63051,   59.43250,    -1.58031,3.60934,6
   175.73356,   59.48750,    -1.67477,3.60734,6
   176.83648,   59.54250,    -1.78683,3.60533,6
   177.93918,   59.59750,    -1.89075,3.60331,6
   179.04274,   59.65250,    -1.94172,3.60128,6
   180.14651,   59.70750,    -1.95053,3.59923,6
   181.25005,   59.76250,    -1.93715,3.59716,6
   182.35465,   59.81750,    -1.90911,3.59508,6
   183.45969,   59.87250,    -1.85750,3.59299,6
   184.56467,   59.92750,    -1.75696,3.59088,6
   185.66977,   59.98250,    -1.58685,3.58876,6
   186.77472,   60.03750,    -1.41101,3.58662,6
   187.87979,   60.09250,    -1.27461,3.58447,6
   188.98456,   60.14750,    -1.17848,3.58231,6
   190.08884,   60.20250,    -1.11226,3.58013,6
   191.19289,   60.25750,    -1.06769,3.57794,6
   192.29575,   60.31250,    -1.03790,3.57574,6
   193.39851,   60.36750,    -1.01783,3.57352,6
   194.50131,   60.42250,    -1.00477,3.57130,6
   195.60349,   60.47750,    -0.99634,3.56906,6
   196.70602,   60.53250,    -0.99128,3.56680,6
   197.80915,   60.58750,    -0.98825,3.56453,6
   198.91202,   60.64250,    -0.98665,3.56225,6
   200.01502,   60.69750,    -0.98634,3.55996,6
   201.11826,   60.75250,    -0.98633,3.55765,6
   202.22107,   60.80750,    -0.98666,3.55532,6
   203.32410,   60.86250,    -0.98750,3.55299,6
   204.42772,   60.91750,    -0.98870,3.55064,6
   205.53113,   60.97250,    -0.98998,3.54827,6
   206.63433,   61.02750,    -0.99115,3.54590,6
   207.73810,   61.08250,    -0.99261,3.54351,6
   208.84157,   61.13750,    -0.99396,3.54110,6
   209.94484,   61.19250,    -0.99530,3.53869,6
   211.04848,   61.24750,    -0.99665,3.53626,6
   212.15177,   61.30250,    -0.99813,3.53381,6
   213.25462,   61.35750,    -0.99948,3.53136,6
   214.35749,   61.41250,    -1.00078,3.52889,6
   215.46084,   61.46750,    -1.00225,3.52641,6
   216.56400,   61.52250,    -1.00384,3.52392,6
   217.66693,   61.57750,    -1.00483,3.52141,6
   218.77007,   61.63250,    -1.00645,3.51889,6
   219.87293,   61.68750,    -1.00797,3.51636,6
   220.97589,   61.74250,    -1.00930,3.51381,6
   222.07913,   61.79750,    -1.01066,3.51125,6
   223.18243,   61.85250,    -1.01202,3.50868,6
   224.28533,   61.90750,    -1.01354,3.50609,6
   225.38816,   61.96250,    -1.01470,3.50350,6
   226.49139,   62.01750,    -1.01610,3.50089,6
   227.59392,   62.07250,    -1.01740,3.49827,6
   228.69657,   62.12750,    -1.01862,3.49563,6
   229.79959,   62.18250,    -1.02004,3.49298,6
   230.90274,   62.23750,    -1.02131,3.49032,6
   232.00585,   62.29250,    -1.02257,3.48765,6
   233.10866,   62.34750,    -1.02387,3.48496,6
   234.21166,   62.40250,    -1.02514,3.48226,6
   235.31444,   62.45750,    -1.02644,3.47955,6
   236.41780,   62.51250,    -1.02756,3.47683,6
   237.52148,   62.56750,    -1.02878,3.47409,6
   238.62464,   62.62250,    -1.02985,3.47134,6
   239.72775,   62.67750,    -1.03121,3.46858,6
   240.83090,   62.73250,    -1.03234,3.46581,6
   241.93439,   62.78750,    -1.03345,3.46302,6
   243.03813,   62.84250,    -1.03470,3.46022,6
   244.14148,   62.89750,    -1.03560,3.45741,6
   245.24474,   62.95250,    -1.03668,3.45459,6
   246.34825,   63.00750,    -1.03785,3.45176,6
   247.45126,   63.06250,    -1.03872,3.44891,6
   248.55408,   63.11750,    -1.03986,3.44605,6
   249.65689,   63.17250,    -1.04092,3.44318,6
   250.76012,   63.22750,    -1.04199,3.44030,6
   251.86352,   63.28250,    -1.04297,3.43740,6
   252.96626,   63.33750,    -1.04393,3.43450,6
   254.06941,   63.39250,    -1.04495,3.43158,6
   255.17229,   63.44750,    -1.04590,3.42865,7
   256.23877,   63.50250,    -1.04983,3.42580,7
   256.99788,   63.55750,    -1.03320,3.42377,7
   257.08953,   63.61250,    -0.90728,3.42352,7
   256.31441,   63.66750,    -0.60844,3.42560,7
   254.80941,   63.72250,    -0.15712,3.42961,7
   252.98029,   63.77750,     0.31821,3.43446,7
   251.11630,   63.83250,     0.69935,3.43936,7
   249.32118,   63.88750,     0.95358,3.44406,7
   247.62453,   63.94250,     1.10076,3.44846,7
   246.02959,   63.99750,     1.17448,3.45258,7
   244.52582,   64.05250,     1.19579,3.45643,7
   243.10612,   64.10750,     1.18550,3.46005,7
   241.76024,   64.16250,     1.15666,3.46346,7
   240.47512,   64.21750,     1.11631,3.46671,7
   239.23871,   64.27250,     1.07512,3.46981,7
   238.04329,   64.32750,     1.03424,3.47279,7
   236.88065,   64.38250,     0.99569,3.47568,7
   235.74059,   64.43750,     0.96229,3.47850,7
   234.61841,   64.49250,     0.93325,3.48127,7
   233.50500,   64.54750,     0.90937,3.48399,7
   232.39718,   64.60250,     0.89329,3.48670,7
   231.29241,   64.65750,     0.87892,3.48938,7
   230.18876,   64.71250,     0.86864,3.49205,7
   229.08341,   64.76750,     0.86213,3.49470,7
   227.97618,   64.82250,     0.85865,3.49735,7
   226.86500,   64.87750,     0.85595,3.50000,7
   225.75000,   64.93250,     0.85623,3.50264,7
   224.63335,   64.98750,     0.85690,3.50528,7
   223.51535,   65.04250,     0.85730,3.50790,7
   222.39547,   65.09750,     0.85884,3.51051,7
   221.27471,   65.15250,     0.85985,3.51312,7
   220.15312,   65.20750,     0.86057,3.51571,7
   219.03306,   65.26250,     0.86190,3.51829,7
   217.91594,   65.31750,     0.86149,3.52084,7
   216.79612,   65.37250,     0.86053,3.52339,7
   215.67859,   65.42750,     0.86101,3.52592,7
   214.56218,   65.48250,     0.86028,3.52843,7
   213.44706,   65.53750,     0.85910,3.53093,7
   212.33382,   65.59250,     0.85836,3.53341,7
   211.22224,   65.64750,     0.85704,3.53587,7
   210.11241,   65.70250,     0.85562,3.53832,7
   209.00306,   65.75750,     0.85451,3.54075,7
   207.89365,   65.81250,     0.85282,3.54317,7
   206.78335,   65.86750,     0.85219,3.54558,7
   205.67435,   65.92250,     0.85206,3.54797,7
   204.56482,   65.97750,     0.85084,3.55034,7
   203.45553,   66.03250,     0.85095,3.55271,7
   202.34800,   66.08750,     0.85053,3.55506,7
   201.24030,   66.14250,     0.84922,3.55739,7
   200.13335,   66.19750,     0.84883,3.55971,7
   199.02823,   66.25250,     0.84840,3.56201,7
   197.92236,   66.30750,     0.84686,3.56430,7
   196.81629,   66.36250,     0.84661,3.56658,7
   195.71012,   66.41750,     0.84607,3.56884,7
   194.60277,   66.47250,     0.84534,3.57109,7
   193.49565,   66.52750,     0.84552,3.57333,7
   192.38918,   66.58250,     0.84529,3.57555,7
   191.28412,   66.63750,     0.84427,3.57776,7
   190.18065,   66.69250,     0.84400,3.57995,7
   189.07900,   66.74750,     0.84231,3.58212,7
   187.97324,   66.80250,     0.84112,3.58429,7
   186.86794,   66.85750,     0.84173,3.58644,7
   185.76700,   66.91250,     0.84112,3.58857,7
   184.66565,   66.96750,     0.83919,3.59068,7
   183.56318,   67.02250,     0.83874,3.59279,7
   182.45988,   67.07750,     0.83807,3.59488,7
   181.35847,   67.13250,     0.83775,3.59696,7
   180.25647,   67.18750,     0.83722,3.59902,7
   179.14971,   67.24250,     0.83633,3.60108,7
   178.04324,   67.29750,     0.83718,3.60312,7
   176.94247,   67.35250,     0.83777,3.60514,7
   175.84453,   67.40750,     0.83537,3.60714,7
   174.74288,   67.46250,     0.83328,3.60913,7
   173.63912,   67.51750,     0.83334,3.61112,7
   172.53930,   67.57250,     0.83322,3.61308,7
   171.44365,   67.62750,     0.83196,3.61502,7
   170.34671,   67.68250,     0.82934,3.61695,7
   169.24606,   67.73750,     0.82841,3.61887,7
   168.14800,   67.79250,     0.82839,3.62077,7
   167.05059,   67.84750,     0.82751,3.62266,7
   165.94730,   67.90250,     0.82621,3.62454,7
   164.84194,   67.95750,     0.82737,3.62641,7
   163.74082,   68.01250,     0.82798,3.62826,7
   162.63941,   68.06750,     0.82660,3.63010,7
   161.53576,   68.12250,     0.82645,3.63193,7
   160.43653,   68.17750,     0.82631,3.63373,7
   159.34029,   68.23250,     0.82430,3.63552,7
   158.24000,   68.28750,     0.82220,3.63730,7
   157.13712,   68.34250,     0.82210,3.63906,7
   156.03806,   68.39750,     0.82206,3.64081,7
   154.94206,   68.45250,     0.82091,3.64254,7
   153.84053,   68.50750,     0.81920,3.64426,7
   152.73806,   68.56250,     0.82052,3.64597,7
   151.64006,   68.61750,     0.82671,3.64766,7
   150.54094,   68.67250,     0.84293,3.64934,7
   149.43718,   68.72750,     0.89103,3.65101,7
   148.34024,   68.78250,     1.00625,3.65265,7
   147.24782,   68.83750,     1.22406,3.65427,7
   146.15029,   68.89250,     1.55329,3.65589,7
   145.05335,   68.94750,     1.92560,3.65749,7
   143.95977,   69.00250,     2.22517,3.65907,7
   142.86412,   69.05750,     2.38469,3.66064,7
   141.76323,   69.11250,     2.40900,3.66221,7
   140.66400,   69.16750,     2.33308,3.66375,7
   139.56735,   69.22250,     2.19220,3.66528,7
   138.46488,   69.27750,     2.00949,3.66680,7
   137.35829,   69.33250,     1.80333,3.66831,7
   136.25700,   69.38750,     1.59978,3.66980,7
   135.15935,   69.44250,     1.42103,3.67127,7
   134.05588,   69.49750,     1.27855,3.67274,7
   132.95359,   69.55250,     1.17484,3.67418,7
   131.86112,   69.60750,     1.09633,3.67560,7
   130.76718,   69.66250,     1.03351,3.67701,7
   129.66659,   69.71750,     0.98914,3.67841,7
   128.56988,   69.77250,     0.95598,3.67979,7
   127.47606,   69.82750,     0.92818,3.68116,7
   126.37465,   69.88250,     0.90652,3.68251,7
   125.27194,   69.93750,     0.89130,3.68386,7
   124.17459,   69.99250,     0.87768,3.68518,7
   123.07747,   70.04750,     0.86471,3.68649,7
   121.97671,   70.10250,     0.85435,3.68778,7
   120.88059,   70.15750,     0.84572,3.68906,7
   119.78359,   70.21250,     0.83661,3.69032,7
   118.68065,   70.26750,     0.82907,3.69158,7
   117.58141,   70.32250,     0.82379,3.69281,7
   116.48841,   70.37750,     0.81648,3.69403,7
   115.39376,   70.43250,     0.80864,3.69523,7
   114.30024,   70.48750,     0.80258,3.69641,7
   113.20412,   70.54250,     0.79605,3.69758,7
   112.10141,   70.59750,     0.79079,3.69875,7
   111.00147,   70.65250,     0.78734,3.69989,7
   109.90500,   70.70750,     0.78221,3.70102,7
   108.80359,   70.76250,     0.77608,3.70214,7
   107.70412,   70.81750,     0.77296,3.70324,7
   106.60718,   70.87250,     0.76784,3.70432,7
   105.50629,   70.92750,     0.76236,3.70539,7
   104.40835,   70.98250,     0.75981,3.70644,7
   103.31353,   71.03750,     0.75505,3.70748,7
   102.21324,   71.09250,     0.75007,3.70850,7
   101.11600,   71.14750,     0.74799,3.70951,7
   100.02329,   71.20250,     0.74359,3.71050,7
    98.92482,   71.25750,     0.73953,3.71148,7
    97.82924,   71.31250,     0.73841,3.71244,7
    96.73635,   71.36750,     0.73534,3.71338,7
    95.63647,   71.42250,     0.73234,3.71431,7
    94.53906,   71.47750,     0.73205,3.71523,7
    93.44512,   71.53250,     0.72951,3.71613,7
    92.34541,   71.58750,     0.72629,3.71702,7
    91.24812,   71.64250,     0.72577,3.71789,7
    90.15371,   71.69750,     0.72244,3.71874,7
    89.05341,   71.75250,     0.71909,3.71958,7
    87.95665,   71.80750,     0.71749,3.72040,7
    86.86176,   71.86250,     0.71326,3.72121,7
    85.76394,   71.91750,     0.70888,3.72200,7
    84.66829,   71.97250,     0.70580,3.72278,7
    83.57294,   72.02750,     0.70008,3.72354,7
    82.47559,   72.08250,     0.69545,3.72429,7
    81.38271,   72.13750,     0.69134,3.72502,7
    80.28606,   72.19250,     0.68475,3.72574,7
    79.19029,   72.24750,     0.67859,3.72644,7
    78.09594,   72.30250,     0.67349,3.72712,7
    77.00118,   72.35750,     0.66829,3.72779,7
    75.91041,   72.41250,     0.66387,3.72844,7
    74.81788,   72.46750,     0.65715,3.72908,7
    73.72571,   72.52250,     0.65072,3.72970,7
    72.63635,   72.57750,     0.63841,3.73030,7
    71.54447,   72.63250,     0.63512,3.73089,7
    70.45565,   72.68750,     0.63173,3.73147,7
    69.36529,   72.74250,     0.62625,3.73203,7
    68.27700,   72.79750,     0.62232,3.73257,7
    67.19194,   72.85250,     0.61694,3.73310,7
    66.10453,   72.90750,     0.61099,3.73361,7
    65.02112,   72.96250,     0.60611,3.73410,7
    63.93553,   73.01750,     0.59972,3.73458,7
    62.85059,   73.07250,     0.59539,3.73505,7
    61.76418,   73.12750,     0.58964,3.73550,7
    60.67465,   73.18250,     0.58518,3.73593,7
    59.58741,   73.23750,     0.58066,3.73635,7
    58.49553,   73.29250,     0.57545,3.73676,7
    57.40382,   73.34750,     0.57214,3.73715,7
    56.31124,   73.40250,     0.56719,3.73753,7
    55.21712,   73.45750,     0.56319,3.73789,7
    54.12471,   73.51250,     0.55861,3.73823,7
    53.02853,   73.56750,     0.55384,3.73856,7
    51.93335,   73.62250,     0.55002,3.73888,7
    50.83553,   73.67750,     0.54459,3.73918,7
    49.73824,   73.73250,     0.54069,3.73946,7
    48.64035,   73.78750,     0.53587,3.73973,7
    47.54271,   73.84250,     0.53106,3.73998,7
    46.44547,   73.89750,     0.52674,3.74022,7
    45.34665,   73.95250,     0.52100,3.74044,7
    44.24929,   74.00750,     0.51721,3.74064,7
    43.15141,   74.06250,     0.51127,3.74083,7
    42.05371,   74.11750,     0.50660,3.74101,7
    40.95694,   74.17250,     0.50129,3.74116,7
    39.85782,   74.22750,     0.49601,3.74131,7
    38.76047,   74.28250,     0.49142,3.74143,7
    37.66018,   74.33750,     0.48594,3.74154,7
    36.56265,   74.39250,     0.48187,3.74164,7
    35.46394,   74.44750,     0.47613,3.74172,7
    34.36512,   74.50250,     0.47133,3.74178,7
    33.26729,   74.55750,     0.46686,3.74183,7
    32.16835,   74.61250,     0.46173,3.74186,7
    31.07088,   74.66750,     0.45745,3.74188,7
    29.97129,   74.72250,     0.45208,3.74188,7
    28.87229,   74.77750,     0.44833,3.74186,7
    27.77194,   74.83250,     0.44419,3.74183,7
    26.67241,   74.88750,     0.44046,3.74178,7
    25.90800,   74.92583,     0.43794,3.74174,7