File: Vertiefung_Polymere/02_Data/PETG.txt
Temp./C,Time/min,DSC/(mW/mg),Sensit./(uV/mW),Segment
    27.97000,0.0000e+000,-7.7201e-003,3.74184,1
    27.87024,5.5000e-002,-3.4323e-003,3.74183,1
    27.76488,    0.11000,-2.9826e-005,3.74183,1
    27.64976,    0.16500, 3.2244e-003,3.74182,1
    27.52447,    0.22000, 6.2649e-003,3.74182,1
    27.38759,    0.27500, 9.2391e-003,3.74181,1
    27.23959,    0.33000, 1.1950e-002,3.74181,1
    27.08247,    0.38500, 1.5218e-002,3.74180,1
    26.91535,    0.44000, 1.8256e-002,3.74179,1
    26.73906,    0.49500, 2.1048e-002,3.74178,1
    26.55165,    0.55000, 2.3429e-002,3.74178,1
    26.35018,    0.60500, 2.5842e-002,3.74176,1
    26.13565,    0.66000, 2.8385e-002,3.74175,1
    25.90853,    0.71500, 3.1698e-002,3.74174,1
    25.66859,    0.77000, 3.4616e-002,3.74172,1
    25.41424,    0.82500, 3.7239e-002,3.74171,1
    25.14418,    0.88000, 4.0205e-002,3.74169,1
    24.85676,    0.93500, 4.3497e-002,3.74167,1
    24.55565,    0.99000, 4.7478e-002,3.74165,1
    24.24471,    1.04500, 5.1457e-002,3.74162,1
    23.92376,    1.10000, 5.5486e-002,3.74159,1
    23.59229,    1.15500, 5.8776e-002,3.74156,1
    23.25453,    1.21000, 6.2623e-002,3.74153,1
    22.90800,    1.26500, 6.5388e-002,3.74150,1
    22.55435,    1.32000, 6.7808e-002,3.74146,1
    22.19029,    1.37500, 7.0342e-002,3.74142,1
    21.81806,    1.43000, 7.2909e-002,3.74138,1
    21.43859,    1.48500, 7.5279e-002,3.74134,1
    21.04918,    1.54000, 7.6927e-002,3.74129,1
    20.64959,    1.59500, 7.9148e-002,3.74124,1
    20.24306,    1.65000, 8.1582e-002,3.74119,1
    19.82718,    1.70500, 8.3736e-002,3.74113,1
    19.40194,    1.76000, 8.5497e-002,3.74107,1
    18.96735,    1.81500, 8.7750e-002,3.74100,1
    18.52447,    1.87000, 9.0100e-002,3.74094,1
    18.07318,    1.92500, 9.2007e-002,3.74086,1
    17.61247,    1.98000, 9.4012e-002,3.74079,1
    17.14159,    2.03500, 9.6214e-002,3.74071,1
    16.66471,    2.09000, 9.8612e-002,3.74062,1
    16.17767,    2.14500,     0.10007,3.74053,1
     5.07241,    3.23417,     0.13079,3.73763,2
   -10.09594,    4.55417,     0.13427,3.73105,2
   -24.82388,    5.87417,     0.11728,3.72177,2
   -30.74659,    7.19417,-1.3630e-002,3.71724,2
   -25.83559,    8.51417,-3.2477e-002,3.72103,2
   -23.04941,    9.83417,-1.2727e-002,3.72304,2
   -21.59388,   11.15417,-4.1153e-003,3.72405,2
   -20.92933,   12.17000,-6.9654e-004,3.72450,3
   -20.62780,   12.22500, 4.1057e-002,3.72471,3
   -19.78921,   12.28000,     0.11809,3.72526,3
   -18.49274,   12.33500, 9.2012e-002,3.72611,3
   -17.03284,   12.39000, 4.5259e-003,3.72704,3
   -15.58754,   12.44500,-8.9532e-002,3.72792,3
   -14.22662,   12.50000,    -0.16446,3.72874,3
   -12.96252,   12.55500,    -0.21439,3.72947,3
   -11.78346,   12.61000,    -0.24272,3.73013,3
   -10.67210,   12.66500,    -0.25594,3.73074,3
    -9.60956,   12.72000,    -0.25882,3.73131,3
    -8.58048,   12.77500,    -0.25574,3.73184,3
    -7.57202,   12.83000,    -0.24966,3.73236,3
    -6.57339,   12.88500,    -0.24263,3.73285,3
    -5.57672,   12.94000,    -0.23629,3.73333,3
    -4.57723,   12.99500,    -0.23098,3.73380,3
    -3.57182,   13.05000,    -0.22692,3.73425,3
    -2.55836,   13.10500,    -0.22447,3.73470,3
    -1.53549,   13.16000,    -0.22355,3.73514,3
    -0.50275,   13.21500,    -0.22335,3.73556,3
     0.53977,   13.27000,    -0.22414,3.73598,3
     1.59180,   13.32500,    -0.22551,3.73639,3
     2.65375,   13.38000,    -0.22780,3.73678,3
     3.72448,   13.43500,    -0.23040,3.73717,3
     4.80325,   13.49000,    -0.23304,3.73754,3
     5.88820,   13.54500,    -0.23605,3.73790,3
     6.97900,   13.60000,    -0.23926,3.73824,3
     8.07548,   13.65500,    -0.24243,3.73857,3
     9.17598,   13.71000,    -0.24527,3.73889,3
    10.28046,   13.76500,    -0.24810,3.73919,3
    11.38839,   13.82000,    -0.25106,3.73948,3
    12.49895,   13.87500,    -0.25388,3.73975,3
    13.61161,   13.93000,    -0.25638,3.74000,3
    14.72618,   13.98500,    -0.25900,3.74024,3
    15.84264,   14.04000,    -0.26129,3.74047,3
    16.95956,   14.09500,    -0.26351,3.74067,3
    18.07720,   14.15000,    -0.26562,3.74086,3
    19.19552,   14.20500,    -0.26773,3.74104,3
    20.31393,   14.26000,    -0.26960,3.74120,3
    21.43279,   14.31500,    -0.27183,3.74134,3
    22.55148,   14.37000,    -0.27357,3.74146,3
    23.67023,   14.42500,    -0.27529,3.74157,3
    24.78869,   14.48000,    -0.27700,3.74166,3
    25.90674,   14.53500,    -0.27864,3.74174,3
    27.02477,   14.59000,    -0.28006,3.74180,3
    28.14292,   14.64500,    -0.28172,3.74184,3
    29.26074,   14.70000,    -0.28327,3.74187,3
    30.37811,   14.75500,    -0.28505,3.74188,3
    31.49507,   14.81000,    -0.28657,3.74187,3
    32.61144,   14.86500,    -0.28822,3.74185,3
    33.72752,   14.92000,    -0.29002,3.74181,3
    34.84344,   14.97500,    -0.29146,3.74176,3
    35.95905,   15.03000,    -0.29310,3.74168,3
    37.07411,   15.08500,    -0.29457,3.74160,3
    38.18869,   15.14000,    -0.29625,3.74149,3
    39.30307,   15.19500,    -0.29771,3.74137,3
    40.41751,   15.25000,    -0.29948,3.74124,3
    41.53120,   15.30500,    -0.30132,3.74108,3
    42.64454,   15.36000,    -0.30307,3.74091,3
    43.75762,   15.41500,    -0.30455,3.74073,3
    44.87034,   15.47000,    -0.30633,3.74053,3
    45.98348,   15.52500,    -0.30818,3.74031,3
    47.09644,   15.58000,    -0.31003,3.74008,3
    48.20880,   15.63500,    -0.31177,3.73983,3
    49.32077,   15.69000,    -0.31367,3.73956,3
    50.43233,   15.74500,    -0.31543,3.73928,3
    51.54434,   15.80000,    -0.31733,3.73898,3
    52.65652,   15.85500,    -0.31927,3.73867,3
    53.76831,   15.91000,    -0.32138,3.73834,3
    54.87969,   15.96500,    -0.32353,3.73800,3
    55.99033,   16.02000,    -0.32564,3.73763,3
    57.10166,   16.07500,    -0.32777,3.73726,3
    58.21348,   16.13000,    -0.33028,3.73686,3
    59.32439,   16.18500,    -0.33259,3.73645,3
    60.43531,   16.24000,    -0.33449,3.73603,3
    61.54659,   16.29500,    -0.33607,3.73559,3
    62.65726,   16.35000,    -0.33737,3.73513,3
    63.76744,   16.40500,    -0.33814,3.73466,3
    64.87761,   16.46000,    -0.33858,3.73417,3
    65.98779,   16.51500,    -0.33949,3.73366,3
    67.09780,   16.57000,    -0.34025,3.73314,3
    68.20797,   16.62500,    -0.34177,3.73260,3
    69.31805,   16.68000,    -0.34376,3.73205,3
    70.42767,   16.73500,    -0.34635,3.73148,3
    71.53718,   16.79000,    -0.34975,3.73090,3
    72.64643,   16.84500,    -0.35286,3.73030,3
    73.75584,   16.90000,    -0.35553,3.72968,3
    74.86505,   16.95500,    -0.35810,3.72905,3
    75.97356,   17.01000,    -0.36154,3.72840,3
    77.08236,   17.06500,    -0.36682,3.72774,3
    78.19097,   17.12000,    -0.37451,3.72706,3
    79.29931,   17.17500,    -0.38409,3.72637,3
    80.40761,   17.23000,    -0.39851,3.72566,3
    81.51598,   17.28500,    -0.42140,3.72493,3
    82.62426,   17.34000,    -0.45033,3.72419,3
    83.73213,   17.39500,    -0.46549,3.72343,3
    84.84010,   17.45000,    -0.49660,3.72266,3
    85.94769,   17.50500,    -0.56120,3.72187,3
    87.05510,   17.56000,    -0.57633,3.72107,3
    88.16284,   17.61500,    -0.56641,3.72025,3
    89.27072,   17.67000,    -0.54915,3.71941,3
    90.37879,   17.72500,    -0.53340,3.71856,3
    91.48652,   17.78000,    -0.52123,3.71770,3
    92.59433,   17.83500,    -0.51221,3.71682,3
    93.70207,   17.89000,    -0.50556,3.71592,3
    94.80982,   17.94500,    -0.50064,3.71500,3
    95.91723,   18.00000,    -0.49711,3.71408,3
    97.02472,   18.05500,    -0.49464,3.71313,3
    98.13208,   18.11000,    -0.49298,3.71217,3
    99.23964,   18.16500,    -0.49229,3.71120,3
   100.34707,   18.22000,    -0.49186,3.71021,3
   101.45349,   18.27500,    -0.49192,3.70920,3
   102.55931,   18.33000,    -0.49203,3.70818,3
   103.66564,   18.38500,    -0.49236,3.70715,3
   104.77228,   18.44000,    -0.49312,3.70610,3
   105.87902,   18.49500,    -0.49379,3.70503,3
   106.98600,   18.55000,    -0.49489,3.70395,3
   108.09298,   18.60500,    -0.49574,3.70285,3
   109.19974,   18.66000,    -0.49679,3.70174,3
   110.30669,   18.71500,    -0.49782,3.70061,3
   111.41349,   18.77000,    -0.49891,3.69946,3
   112.51916,   18.82500,    -0.49994,3.69831,3
   113.62372,   18.88000,    -0.50142,3.69714,3
   114.72789,   18.93500,    -0.50221,3.69595,3
   115.83362,   18.99000,    -0.50333,3.69475,3
   116.93967,   19.04500,    -0.50462,3.69353,3
   118.04515,   19.10000,    -0.50564,3.69229,3
   119.15089,   19.15500,    -0.50679,3.69104,3
   120.25708,   19.21000,    -0.50749,3.68978,3
   121.36289,   19.26500,    -0.50859,3.68850,3
   122.46811,   19.32000,    -0.50978,3.68721,3
   123.57295,   19.37500,    -0.51068,3.68590,3
   124.67807,   19.43000,    -0.51166,3.68457,3
   125.78346,   19.48500,    -0.51279,3.68323,3
   126.88910,   19.54000,    -0.51361,3.68188,3
   127.99479,   19.59500,    -0.51469,3.68051,3
   129.10031,   19.65000,    -0.51570,3.67913,3
   130.20556,   19.70500,    -0.51669,3.67773,3
   131.31046,   19.76000,    -0.51755,3.67631,3
   132.41557,   19.81500,    -0.51836,3.67489,3
   133.52072,   19.87000,    -0.51928,3.67344,3
   134.62603,   19.92500,    -0.52013,3.67198,3
   135.73113,   19.98000,    -0.52120,3.67051,3
   136.83577,   20.03500,    -0.52212,3.66902,3
   137.94064,   20.09000,    -0.52300,3.66752,3
   139.04547,   20.14500,    -0.52402,3.66600,3
   140.14985,   20.20000,    -0.52483,3.66447,3
   141.25428,   20.25500,    -0.52575,3.66292,3
   142.35875,   20.31000,    -0.52661,3.66136,3
   143.46349,   20.36500,    -0.52751,3.65979,3
   144.56833,   20.42000,    -0.52846,3.65819,3
   145.67302,   20.47500,    -0.52934,3.65659,3
   146.77752,   20.53000,    -0.53005,3.65497,3
   147.88182,   20.58500,    -0.53111,3.65333,3
   148.98585,   20.64000,    -0.53185,3.65169,3
   150.08952,   20.69500,    -0.53244,3.65002,3
   151.19344,   20.75000,    -0.53323,3.64835,3
   152.29779,   20.80500,    -0.53403,3.64665,3
   153.40218,   20.86000,    -0.53477,3.64495,3
   154.50657,   20.91500,    -0.53558,3.64322,3
   155.61080,   20.97000,    -0.53648,3.64149,3
   156.71500,   21.02500,    -0.53716,3.63974,3
   157.81987,   21.08000,    -0.53777,3.63797,3
   158.92428,   21.13500,    -0.53851,3.63619,3
   160.02869,   21.19000,    -0.53930,3.63440,3
   161.13307,   21.24500,    -0.53995,3.63259,3
   162.23718,   21.30000,    -0.54069,3.63077,3
   163.34172,   21.35500,    -0.54153,3.62893,3
   164.44516,   21.41000,    -0.54222,3.62708,3
   165.54798,   21.46500,    -0.54317,3.62522,3
   166.65174,   21.52000,    -0.54419,3.62334,3
   167.75521,   21.57500,    -0.54577,3.62145,3
   168.85908,   21.63000,    -0.54719,3.61954,3
   169.96321,   21.68500,    -0.54793,3.61762,3
   171.06698,   21.74000,    -0.54814,3.61568,3
   172.17134,   21.79500,    -0.54838,3.61373,3
   173.27590,   21.85000,    -0.54930,3.61177,3
   174.38054,   21.90500,    -0.55019,3.60979,3
   175.48452,   21.96000,    -0.55110,3.60779,3
   176.58798,   22.01500,    -0.55209,3.60579,3
   177.69164,   22.07000,    -0.55303,3.60377,3
   178.79569,   22.12500,    -0.55390,3.60173,3
   179.89941,   22.18000,    -0.55513,3.59969,3
   181.00351,   22.23500,    -0.55638,3.59762,3
   182.10752,   22.29000,    -0.55751,3.59555,3
   183.21121,   22.34500,    -0.55890,3.59346,3
   184.31528,   22.40000,    -0.56030,3.59136,3
   185.41890,   22.45500,    -0.56165,3.58924,3
   186.52203,   22.51000,    -0.56316,3.58711,3
   187.62493,   22.56500,    -0.56434,3.58497,3
   188.72808,   22.62000,    -0.56603,3.58281,3
   189.83108,   22.67500,    -0.56762,3.58064,3
   190.93433,   22.73000,    -0.56902,3.57845,3
   192.03752,   22.78500,    -0.57048,3.57626,3
   193.14097,   22.84000,    -0.57208,3.57404,3
   194.24447,   22.89500,    -0.57360,3.57182,3
   195.34797,   22.95000,    -0.57538,3.56958,3
   196.45159,   23.00500,    -0.57651,3.56732,3
   197.55515,   23.06000,    -0.57818,3.56506,3
   198.65849,   23.11500,    -0.57959,3.56278,3
   199.76143,   23.17000,    -0.58101,3.56048,3
   200.86397,   23.22500,    -0.58223,3.55818,3
   201.96692,   23.28000,    -0.58344,3.55586,3
   203.07005,   23.33500,    -0.58458,3.55353,3
   204.17349,   23.39000,    -0.58574,3.55118,3
   205.27715,   23.44500,    -0.58681,3.54882,3
   206.38120,   23.50000,    -0.58807,3.54644,3
   207.48523,   23.55500,    -0.58917,3.54406,3
   208.58905,   23.61000,    -0.59030,3.54165,3
   209.69279,   23.66500,    -0.59117,3.53924,3
   210.79649,   23.72000,    -0.59204,3.53681,3
   211.89989,   23.77500,    -0.59294,3.53437,3
   213.00323,   23.83000,    -0.59380,3.53192,3
   214.10626,   23.88500,    -0.59485,3.52946,3
   215.20938,   23.94000,    -0.59578,3.52698,3
   216.31254,   23.99500,    -0.59669,3.52449,3
   217.41554,   24.05000,    -0.59747,3.52198,3
   218.51864,   24.10500,    -0.59852,3.51946,3
   219.62233,   24.16000,    -0.59952,3.51693,3
   220.72593,   24.21500,    -0.60051,3.51439,3
   221.82941,   24.27000,    -0.60143,3.51183,3
   222.93267,   24.32500,    -0.60235,3.50926,3
   224.03600,   24.38000,    -0.60321,3.50668,3
   225.13887,   24.43500,    -0.60419,3.50409,3
   226.24221,   24.49000,    -0.60497,3.50148,3
   227.34562,   24.54500,    -0.60613,3.49886,3
   228.44816,   24.60000,    -0.60737,3.49623,3
   229.55151,   24.65500,    -0.60839,3.49358,3
   230.65492,   24.71000,    -0.60930,3.49092,3
   231.75836,   24.76500,    -0.61038,3.48825,3
   232.86218,   24.82000,    -0.61125,3.48556,3
   233.96511,   24.87500,    -0.61210,3.48287,3
   235.06756,   24.93000,    -0.61296,3.48016,3
   236.16954,   24.98500,    -0.61389,3.47744,3
   237.27162,   25.04000,    -0.61462,3.47471,3
   238.37413,   25.09500,    -0.61515,3.47197,3
   239.47730,   25.15000,    -0.61563,3.46921,3
   240.58128,   25.20500,    -0.61646,3.46644,3
   241.68515,   25.26000,    -0.61744,3.46365,3
   242.78918,   25.31500,    -0.61857,3.46086,3
   243.89307,   25.37000,    -0.61988,3.45805,3
   244.99631,   25.42500,    -0.62159,3.45523,3
   246.09880,   25.48000,    -0.62362,3.45240,3
   247.20079,   25.53500,    -0.62546,3.44956,3
   248.30287,   25.59000,    -0.62711,3.44670,3
   249.40526,   25.64500,    -0.62881,3.44384,3
   250.50805,   25.70000,    -0.63011,3.44096,3
   251.61116,   25.75500,    -0.63126,3.43807,3
   252.71423,   25.81000,    -0.63241,3.43516,3
   253.81763,   25.86500,    -0.63325,3.43224,3
   254.91722,   25.92000,    -0.63322,3.42933,4
   256.00988,   25.97500,    -0.63455,3.42641,4
   256.88029,   26.03000,    -0.64462,3.42409,4
   257.17047,   26.08500,    -0.60519,3.42331,4
   256.61723,   26.14000,    -0.45585,3.42479,4
   255.25971,   26.19500,    -0.17848,3.42841,4
   253.47606,   26.25000,     0.15730,3.43315,4
   251.60653,   26.30500,     0.43300,3.43808,4
   249.79565,   26.36000,     0.60980,3.44282,4
   248.08835,   26.41500,     0.70141,3.44726,4
   246.48665,   26.47000,     0.73118,3.45140,4
   244.98018,   26.52500,     0.72666,3.45527,4
   243.55300,   26.58000,     0.70478,3.45891,4
   242.18506,   26.63500,     0.67236,3.46239,4
   240.87006,   26.69000,     0.64274,3.46571,4
   239.60747,   26.74500,     0.61443,3.46889,4
   238.39377,   26.80000,     0.58403,3.47192,4
   237.22541,   26.85500,     0.55751,3.47483,4
   236.09218,   26.91000,     0.53223,3.47764,4
   234.97818,   26.96500,     0.50778,3.48038,4
   233.87194,   27.02000,     0.49176,3.48310,4
   232.76624,   27.07500,     0.48036,3.48580,4
   231.65671,   27.13000,     0.47177,3.48850,4
   230.54759,   27.18500,     0.46989,3.49118,4
   229.43747,   27.24000,     0.46763,3.49385,4
   228.32353,   27.29500,     0.46469,3.49652,4
   227.20435,   27.35000,     0.46615,3.49919,4
   226.08124,   27.40500,     0.46680,3.50186,4
   224.96053,   27.46000,     0.46697,3.50451,4
   223.84371,   27.51500,     0.46864,3.50713,4
   222.72812,   27.57000,     0.46692,3.50974,4
   221.60953,   27.62500,     0.46515,3.51234,4
   220.48982,   27.68000,     0.46728,3.51493,4
   219.36959,   27.73500,     0.46629,3.51751,4
   218.25041,   27.79000,     0.46559,3.52008,4
   217.13247,   27.84500,     0.46722,3.52263,4
   216.01718,   27.90000,     0.46513,3.52515,4
   214.90065,   27.95500,     0.46434,3.52767,4
   213.78547,   28.01000,     0.46557,3.53017,4
   212.67094,   28.06500,     0.46361,3.53266,4
   211.55882,   28.12000,     0.46359,3.53513,4
   210.44930,   28.17500,     0.46394,3.53758,4
   209.33753,   28.23000,     0.46146,3.54002,4
   208.22529,   28.28500,     0.46140,3.54245,4
   207.11565,   28.34000,     0.46231,3.54486,4
   206.00465,   28.39500,     0.46036,3.54725,4
   204.89471,   28.45000,     0.46105,3.54964,4
   203.78541,   28.50500,     0.46108,3.55201,4
   202.67759,   28.56000,     0.45915,3.55436,4
   201.57100,   28.61500,     0.45967,3.55669,4
   200.46606,   28.67000,     0.45948,3.55901,4
   199.36065,   28.72500,     0.45753,3.56132,4
   198.25541,   28.78000,     0.45859,3.56361,4
   197.15076,   28.83500,     0.45781,3.56589,4
   196.04530,   28.89000,     0.45615,3.56815,4
   194.94118,   28.94500,     0.45740,3.57040,4
   193.83347,   29.00000,     0.45687,3.57265,4
   192.72453,   29.05500,     0.45672,3.57488,4
   191.61729,   29.11000,     0.45860,3.57709,4
   190.51294,   29.16500,     0.45772,3.57929,4
   189.40641,   29.22000,     0.45586,3.58148,4
   188.29576,   29.27500,     0.45773,3.58366,4
   187.18623,   29.33000,     0.45758,3.58582,4
   186.08218,   29.38500,     0.45760,3.58796,4
   184.98788,   29.44000,     0.45766,3.59007,4
   183.89424,   29.49500,     0.45319,3.59216,4
   182.79159,   29.55000,     0.45169,3.59425,4
   181.68282,   29.60500,     0.45400,3.59635,4
   180.57765,   29.66000,     0.45465,3.59842,4
   179.48082,   29.71500,     0.45492,3.60046,4
   178.38782,   29.77000,     0.45370,3.60249,4
   177.28659,   29.82500,     0.45062,3.60451,4
   176.18059,   29.88000,     0.45182,3.60653,4
   175.07612,   29.93500,     0.45430,3.60853,4
   173.97765,   29.99000,     0.45323,3.61051,4
   172.88270,   30.04500,     0.45230,3.61247,4
   171.78076,   30.10000,     0.45114,3.61442,4
   170.66900,   30.15500,     0.45061,3.61638,4
   169.56141,   30.21000,     0.45420,3.61832,4
   168.46212,   30.26500,     0.45473,3.62023,4
   167.37041,   30.32000,     0.45168,3.62211,4
   166.27647,   30.37500,     0.44978,3.62398,4
   165.16941,   30.43000,     0.44907,3.62586,4
   164.05682,   30.48500,     0.45051,3.62773,4
   162.95235,   30.54000,     0.45392,3.62958,4
   161.85853,   30.59500,     0.45308,3.63139,4
   160.77071,   30.65000,     0.44960,3.63318,4
   159.67741,   30.70500,     0.44761,3.63497,4
   158.57529,   30.76000,     0.44666,3.63676,4
   157.47112,   30.81500,     0.44823,3.63853,4
   156.37388,   30.87000,     0.45021,3.64028,4
   155.27971,   30.92500,     0.44841,3.64201,4
   154.18018,   30.98000,     0.44653,3.64373,4
   153.07429,   31.03500,     0.44863,3.64545,4
   151.96906,   31.09000,     0.44924,3.64716,4
   150.86982,   31.14500,     0.44955,3.64884,4
   149.77118,   31.20000,     0.44914,3.65050,4
   148.66447,   31.25500,     0.44750,3.65217,4
   147.55588,   31.31000,     0.44890,3.65382,4
   146.45553,   31.36500,     0.45108,3.65544,4
   145.36553,   31.42000,     0.44850,3.65704,4
   144.27688,   31.47500,     0.44565,3.65862,4
   143.17788,   31.53000,     0.44413,3.66020,4
   142.07188,   31.58500,     0.44495,3.66177,4
   140.97265,   31.64000,     0.44779,3.66332,4
   139.88106,   31.69500,     0.44768,3.66484,4
   138.78888,   31.75000,     0.44480,3.66636,4
   137.68665,   31.80500,     0.44505,3.66787,4
   136.57976,   31.86000,     0.44715,3.66937,4
   135.47871,   31.91500,     0.44832,3.67085,4
   134.38629,   31.97000,     0.44838,3.67230,4
   133.29135,   32.02500,     0.44560,3.67374,4
   132.18747,   32.08000,     0.44458,3.67518,4
   131.08512,   32.13500,     0.44669,3.67660,4
   129.98994,   32.19000,     0.44648,3.67800,4
   128.89347,   32.24500,     0.44413,3.67939,4
   127.79194,   32.30000,     0.44417,3.68076,4
   126.69000,   32.35500,     0.44447,3.68213,4
   125.59365,   32.41000,     0.44493,3.68347,4
   124.49841,   32.46500,     0.44379,3.68479,4
   123.39412,   32.52000,     0.44256,3.68611,4
   122.28947,   32.57500,     0.44437,3.68742,4
   121.19388,   32.63000,     0.44523,3.68870,4
   120.10288,   32.68500,     0.44308,3.68996,4
   119.00424,   32.74000,     0.44098,3.69121,4
   117.90335,   32.79500,     0.44167,3.69245,4
   116.80541,   32.85000,     0.44235,3.69368,4
   115.71324,   32.90500,     0.44192,3.69488,4
   114.61471,   32.96000,     0.43973,3.69607,4
   113.51159,   33.01500,     0.44035,3.69726,4
   112.41700,   33.07000,     0.44183,3.69841,4
   111.32582,   33.12500,     0.44038,3.69956,4
   110.22782,   33.18000,     0.43800,3.70069,4
   109.12612,   33.23500,     0.43882,3.70181,4
   108.02888,   33.29000,     0.44001,3.70291,4
   106.93571,   33.34500,     0.43877,3.70400,4
   105.83553,   33.40000,     0.43740,3.70507,4
   104.73271,   33.45500,     0.43814,3.70613,4
   103.63653,   33.51000,     0.43927,3.70718,4
   102.54618,   33.56500,     0.43812,3.70820,4
   101.44712,   33.62000,     0.43561,3.70921,4
   100.34647,   33.67500,     0.43625,3.71021,4
    99.25076,   33.73000,     0.43768,3.71119,4
    98.15871,   33.78500,     0.43600,3.71215,4
    97.05812,   33.84000,     0.43443,3.71310,4
    95.95794,   33.89500,     0.43560,3.71404,4
    94.86365,   33.95000,     0.43578,3.71496,4
    93.76741,   34.00500,     0.43437,3.71586,4
    92.66688,   34.06000,     0.43393,3.71676,4
    91.56953,   34.11500,     0.43461,3.71763,4
    90.47588,   34.17000,     0.43385,3.71849,4
    89.37712,   34.22500,     0.43243,3.71933,4
    88.27806,   34.28000,     0.43269,3.72016,4
    87.18547,   34.33500,     0.43331,3.72097,4
    86.09247,   34.39000,     0.43163,3.72177,4
    84.99659,   34.44500,     0.43017,3.72255,4
    83.90141,   34.50000,     0.43055,3.72332,4
    82.81012,   34.55500,     0.42990,3.72406,4
    81.71518,   34.61000,     0.42794,3.72480,4
    80.61906,   34.66500,     0.42745,3.72552,4
    79.52906,   34.72000,     0.42669,3.72622,4
    78.43818,   34.77500,     0.42297,3.72691,4
    77.34282,   34.83000,     0.41981,3.72758,4
    76.25182,   34.88500,     0.41653,3.72824,4
    75.16518,   34.94000,     0.41005,3.72888,4
    74.07435,   34.99500,     0.40159,3.72950,4
    72.98418,   35.05000,     0.39391,3.73011,4
    71.90053,   35.10500,     0.38531,3.73070,4
    70.81529,   35.16000,     0.37526,3.73128,4
    69.72724,   35.21500,     0.36686,3.73184,4
    68.64259,   35.27000,     0.36000,3.73239,4
    67.55923,   35.32500,     0.35203,3.73292,4
    66.46994,   35.38000,     0.34527,3.73344,4
    65.38041,   35.43500,     0.34115,3.73394,4
    64.29459,   35.49000,     0.33624,3.73443,4
    63.20300,   35.54500,     0.33136,3.73490,4
    62.10853,   35.60000,     0.32887,3.73536,4
    61.01688,   35.65500,     0.32618,3.73580,4
    59.92294,   35.71000,     0.32253,3.73623,4
    58.82476,   35.76500,     0.32047,3.73664,4
    57.73276,   35.82000,     0.31953,3.73704,4
    56.63629,   35.87500,     0.31644,3.73742,4
    55.53653,   35.93000,     0.31435,3.73778,4
    54.43971,   35.98500,     0.31348,3.73813,4
    53.34424,   36.04000,     0.31153,3.73847,4
    52.24500,   36.09500,     0.30925,3.73879,4
    51.14571,   36.15000,     0.30871,3.73909,4
    50.05041,   36.20500,     0.30730,3.73938,4
    48.95135,   36.26000,     0.30472,3.73965,4
    47.85012,   36.31500,     0.30389,3.73991,4
    46.75453,   36.37000,     0.30291,3.74015,4
    45.65629,   36.42500,     0.30051,3.74038,4
    44.55588,   36.48000,     0.29963,3.74059,4
    43.45894,   36.53500,     0.29909,3.74078,4
    42.36124,   36.59000,     0.29666,3.74096,4
    41.26006,   36.64500,     0.29563,3.74112,4
    40.16182,   36.70000,     0.29525,3.74127,4
    39.06635,   36.75500,     0.29312,3.74140,4
    37.96559,   36.81000,     0.29155,3.74151,4
    36.86547,   36.86500,     0.29134,3.74161,4
    35.76888,   36.92000,     0.29001,3.74170,4
    34.66882,   36.97500,     0.28823,3.74176,4
    33.56965,   37.03000,     0.28763,3.74182,4
    32.47341,   37.08500,     0.28633,3.74185,4
    31.37382,   37.14000,     0.28439,3.74187,4
    30.27347,   37.19500,     0.28384,3.74188,4
    29.17682,   37.25000,     0.28318,3.74187,4
    28.07741,   37.30500,     0.28118,3.74184,4
    26.97588,   37.36000,     0.28038,3.74180,4
    25.87924,   37.41500,     0.27992,3.74174,4
    24.78000,   37.47000,     0.27795,3.74166,4
    23.67841,   37.52500,     0.27692,3.74157,4
    22.58047,   37.58000,     0.27653,3.74147,4
    21.48153,   37.63500,     0.27466,3.74134,4
    20.37941,   37.69000,     0.27350,3.74120,4
    19.28094,   37.74500,     0.27331,3.74105,4
    18.18265,   37.80000,     0.27153,3.74088,4
    17.08100,   37.85500,     0.27020,3.74070,4
    15.98212,   37.91000,     0.26989,3.74049,4
    14.88341,   37.96500,     0.26825,3.74028,4
    13.78171,   38.02000,     0.26667,3.74004,4
    12.68188,   38.07500,     0.26652,3.73979,4
    11.58329,   38.13000,     0.26491,3.73953,4
    10.48000,   38.18500,     0.26341,3.73925,4
     9.37835,   38.24000,     0.26315,3.73895,4
     8.27835,   38.29500,     0.26200,3.73863,4
     7.17476,   38.35000,     0.26021,3.73830,4
     6.07159,   38.40500,     0.25992,3.73796,4
     4.96888,   38.46000,     0.25864,3.73760,4
     3.86118,   38.51500,     0.25714,3.73722,4
     2.75694,   38.57000,     0.25719,3.73682,4
     1.65188,   38.62500,     0.25592,3.73641,4
     0.54565,   38.68000,     0.25437,3.73598,4
    -0.55694,   38.73500,     0.25392,3.73554,4
    -1.65794,   38.79000,     0.25236,3.73509,4
    -2.76129,   38.84500,     0.25050,3.73461,4
    -3.86165,   38.90000,     0.24974,3.73412,4
    -4.95753,   38.95500,     0.24834,3.73362,4
    -6.05559,   39.01000,     0.24625,3.73310,4
    -7.14400,   39.06500,     0.24574,3.73257,4
    -8.21718,   39.12000,     0.24475,3.73203,4
    -9.27647,   39.17500,     0.24165,3.73148,4
   -10.31988,   39.23000,     0.23859,3.73093,4
   -11.34259,   39.28500,     0.23468,3.73038,4
   -12.35247,   39.34000,     0.22978,3.72981,4
   -13.34759,   39.39500,     0.22576,3.72925,4
   -14.32576,   39.45000,     0.22122,3.72868,4
   -15.29076,   39.50500,     0.21639,3.72810,4
   -16.24171,   39.56000,     0.21249,3.72753,4
   -17.17718,   39.61500,     0.20814,3.72695,4
   -18.71767,   39.70833,     0.20174,3.72596,5
   -20.58506,   41.02833,-8.8401e-003,3.72473,5
   -20.18676,   42.34833, 3.1716e-003,3.72500,5
   -20.08776,   43.66833, 4.5608e-003,3.72507,5
   -20.01371,   44.98833, 4.4666e-003,3.72512,5
   -20.00406,   46.30833, 5.3399e-003,3.72512,5
   -20.01541,   47.62833, 5.1581e-003,3.72511,5
   -20.01835,   48.94833, 4.6804e-003,3.72511,5
   -20.01041,   49.69417, 5.3391e-003,3.72512,6
   -19.64000,   49.74917, 5.3724e-002,3.72536,6
   -18.71913,   49.80416, 7.1308e-002,3.72596,6
   -17.39264,   49.85917,-2.0232e-002,3.72681,6
   -15.94610,   49.91417,    -0.13796,3.72771,6
   -14.53241,   49.96917,    -0.22804,3.72856,6
   -13.20775,   50.02417,    -0.27965,3.72933,6
   -11.98030,   50.07917,    -0.29946,3.73002,6
   -10.83407,   50.13417,    -0.30008,3.73065,6
    -9.75080,   50.18917,    -0.29049,3.73123,6
    -8.71375,   50.24417,    -0.27694,3.73178,6
    -7.70720,   50.29917,    -0.26322,3.73229,6
    -6.71754,   50.35417,    -0.25125,3.73278,6
    -5.73505,   50.40917,    -0.24217,3.73325,6
    -4.75387,   50.46417,    -0.23546,3.73371,6
    -3.76857,   50.51917,    -0.23148,3.73416,6
    -2.77582,   50.57417,    -0.22966,3.73460,6
    -1.77411,   50.62917,    -0.22977,3.73504,6
    -0.76233,   50.68417,    -0.23122,3.73546,6
     0.25946,   50.73917,    -0.23328,3.73587,6
     1.29108,   50.79417,    -0.23619,3.73627,6
     2.33270,   50.84917,    -0.23930,3.73667,6
     3.38387,   50.90417,    -0.24236,3.73705,6
     4.44300,   50.95917,    -0.24599,3.73742,6
     5.50992,   51.01417,    -0.24933,3.73778,6
     6.58390,   51.06917,    -0.25265,3.73812,6
     7.66395,   51.12417,    -0.25587,3.73845,6
     8.74893,   51.17916,    -0.25914,3.73877,6
     9.83792,   51.23417,    -0.26187,3.73907,6
    10.93134,   51.28917,    -0.26478,3.73936,6
    12.02900,   51.34417,    -0.26725,3.73964,6
    13.12944,   51.39917,    -0.26991,3.73990,6
    14.23230,   51.45417,    -0.27246,3.74014,6
    15.33736,   51.50917,    -0.27457,3.74037,6
    16.44384,   51.56417,    -0.27686,3.74058,6
    17.55105,   51.61917,    -0.27871,3.74078,6
    18.65908,   51.67417,    -0.28048,3.74096,6
    19.76821,   51.72917,    -0.28249,3.74112,6
    20.87789,   51.78417,    -0.28415,3.74127,6
    21.98761,   51.83917,    -0.28599,3.74140,6
    23.09726,   51.89417,    -0.28732,3.74152,6
    24.20733,   51.94917,    -0.28897,3.74162,6
    25.31777,   52.00417,    -0.29075,3.74170,6
    26.42810,   52.05917,    -0.29213,3.74177,6
    27.53839,   52.11417,    -0.29359,3.74182,6
    28.64867,   52.16917,    -0.29519,3.74186,6
    29.75854,   52.22417,    -0.29681,3.74187,6
    30.86838,   52.27917,    -0.29828,3.74188,6
    31.97782,   52.33417,    -0.29963,3.74186,6
    33.08703,   52.38917,    -0.30120,3.74183,6
    34.19613,   52.44417,    -0.30277,3.74179,6
    35.30518,   52.49917,    -0.30451,3.74173,6
    36.41411,   52.55416,    -0.30613,3.74165,6
    37.52300,   52.60917,    -0.30753,3.74156,6
    38.63225,   52.66417,    -0.30932,3.74145,6
    39.74090,   52.71917,    -0.31083,3.74132,6
    40.84956,   52.77417,    -0.31248,3.74118,6
    41.95821,   52.82917,    -0.31419,3.74102,6
    43.06648,   52.88417,    -0.31579,3.74085,6
    44.17389,   52.93917,    -0.31745,3.74066,6
    45.28148,   52.99417,    -0.31899,3.74045,6
    46.38952,   53.04917,    -0.32064,3.74023,6
    47.49741,   53.10417,    -0.32233,3.73999,6
    48.60492,   53.15917,    -0.32425,3.73974,6
    49.71261,   53.21417,    -0.32586,3.73947,6
    50.82072,   53.26917,    -0.32768,3.73918,6
    51.92869,   53.32417,    -0.32936,3.73888,6
    53.03643,   53.37917,    -0.33108,3.73856,6
    54.14390,   53.43417,    -0.33286,3.73823,6
    55.25161,   53.48917,    -0.33484,3.73788,6
    56.35946,   53.54417,    -0.33654,3.73751,6
    57.46713,   53.59917,    -0.33834,3.73713,6
    58.57448,   53.65417,    -0.34024,3.73673,6
    59.68172,   53.70917,    -0.34215,3.73632,6
    60.78928,   53.76417,    -0.34417,3.73589,6
    61.89685,   53.81917,    -0.34611,3.73544,6
    63.00385,   53.87417,    -0.34816,3.73498,6
    64.11043,   53.92916,    -0.35019,3.73451,6
    65.21710,   53.98417,    -0.35241,3.73401,6
    66.32351,   54.03917,    -0.35479,3.73351,6
    67.43021,   54.09417,    -0.35736,3.73298,6
    68.53711,   54.14917,    -0.36004,3.73244,6
    69.64402,   54.20417,    -0.36311,3.73189,6
    70.75054,   54.25917,    -0.36614,3.73131,6
    71.85688,   54.31417,    -0.36990,3.73073,6
    72.96364,   54.36917,    -0.37471,3.73012,6
    74.07090,   54.42417,    -0.37993,3.72950,6
    75.17749,   54.47917,    -0.38681,3.72887,6
    76.28408,   54.53417,    -0.39592,3.72822,6
    77.39143,   54.58917,    -0.40847,3.72755,6
    78.49836,   54.64417,    -0.42538,3.72687,6
    79.60470,   54.69917,    -0.44752,3.72617,6
    80.71067,   54.75417,    -0.47226,3.72546,6
    81.81621,   54.80917,    -0.49030,3.72473,6
    82.92120,   54.86417,    -0.49540,3.72399,6
    84.02662,   54.91917,    -0.49251,3.72323,6
    85.13241,   54.97417,    -0.48846,3.72245,6
    86.23834,   55.02917,    -0.48583,3.72166,6
    87.34451,   55.08417,    -0.48409,3.72086,6
    88.45105,   55.13917,    -0.48356,3.72003,6
    89.55766,   55.19417,    -0.48368,3.71920,6
    90.66380,   55.24917,    -0.48379,3.71834,6
    91.77008,   55.30416,    -0.48479,3.71747,6
    92.87623,   55.35917,    -0.48552,3.71659,6
    93.98211,   55.41417,    -0.48641,3.71569,6
    95.08774,   55.46917,    -0.48737,3.71477,6
    96.19341,   55.52417,    -0.48832,3.71384,6
    97.29903,   55.57917,    -0.48945,3.71290,6
    98.40428,   55.63417,    -0.49050,3.71194,6
    99.50931,   55.68917,    -0.49158,3.71096,6
   100.61439,   55.74417,    -0.49242,3.70997,6
   101.71911,   55.79917,    -0.49321,3.70896,6
   102.82405,   55.85417,    -0.49439,3.70794,6
   103.92970,   55.90917,    -0.49545,3.70690,6
   105.03551,   55.96417,    -0.49648,3.70584,6
   106.14138,   56.01917,    -0.49771,3.70477,6
   107.24697,   56.07417,    -0.49903,3.70369,6
   108.35246,   56.12917,    -0.50013,3.70259,6
   109.45770,   56.18417,    -0.50112,3.70148,6
   110.56252,   56.23917,    -0.50190,3.70035,6
   111.66720,   56.29417,    -0.50291,3.69920,6
   112.77221,   56.34917,    -0.50386,3.69804,6
   113.87789,   56.40417,    -0.50483,3.69686,6
   114.98361,   56.45917,    -0.50618,3.69567,6
   116.08846,   56.51417,    -0.50713,3.69447,6
   117.19331,   56.56917,    -0.50841,3.69325,6
   118.29825,   56.62417,    -0.50914,3.69201,6
   119.40303,   56.67916,    -0.51020,3.69076,6
   120.50841,   56.73417,    -0.51137,3.68949,6
   121.61416,   56.78917,    -0.51239,3.68821,6
   122.71939,   56.84417,    -0.51340,3.68691,6
   123.82389,   56.89917,    -0.51445,3.68560,6
   124.92756,   56.95417,    -0.51550,3.68427,6
   126.03151,   57.00917,    -0.51655,3.68293,6
   127.13577,   57.06417,    -0.51725,3.68158,6
   128.23975,   57.11917,    -0.51833,3.68021,6
   129.34366,   57.17417,    -0.51929,3.67882,6
   130.44775,   57.22917,    -0.52028,3.67742,6
   131.55218,   57.28417,    -0.52120,3.67600,6
   132.65667,   57.33917,    -0.52241,3.67457,6
   133.76144,   57.39417,    -0.52355,3.67313,6
   134.86620,   57.44917,    -0.52480,3.67166,6
   135.97080,   57.50417,    -0.52568,3.67019,6
   137.07503,   57.55917,    -0.52662,3.66870,6
   138.17859,   57.61417,    -0.52765,3.66719,6
   139.28241,   57.66917,    -0.52860,3.66567,6
   140.38651,   57.72417,    -0.52962,3.66414,6
   141.49082,   57.77917,    -0.53079,3.66259,6
   142.59507,   57.83417,    -0.53163,3.66103,6
   143.69923,   57.88917,    -0.53283,3.65945,6
   144.80364,   57.94417,    -0.53386,3.65785,6
   145.90738,   57.99917,    -0.53479,3.65625,6
   147.01049,   58.05416,    -0.53581,3.65463,6
   148.11408,   58.10917,    -0.53665,3.65299,6
   149.21780,   58.16417,    -0.53761,3.65134,6
   150.32177,   58.21917,    -0.53872,3.64967,6
   151.42603,   58.27417,    -0.53975,3.64799,6
   152.53012,   58.32917,    -0.54082,3.64630,6
   153.63407,   58.38417,    -0.54176,3.64459,6
   154.73846,   58.43917,    -0.54299,3.64286,6
   155.84259,   58.49417,    -0.54403,3.64112,6
   156.94620,   58.54917,    -0.54495,3.63937,6
   158.05031,   58.60417,    -0.54595,3.63760,6
   159.15472,   58.65917,    -0.54705,3.63582,6
   160.25871,   58.71417,    -0.54804,3.63402,6
   161.36279,   58.76917,    -0.54911,3.63221,6
   162.46667,   58.82417,    -0.55010,3.63039,6
   163.57003,   58.87917,    -0.55115,3.62855,6
   164.67336,   58.93417,    -0.55210,3.62670,6
   165.77700,   58.98917,    -0.55326,3.62483,6
   166.88067,   59.04417,    -0.55419,3.62295,6
   167.98418,   59.09917,    -0.55508,3.62105,6
   169.08793,   59.15417,    -0.55567,3.61914,6
   170.19171,   59.20917,    -0.55549,3.61722,6
   171.29498,   59.26417,    -0.55475,3.61528,6
   172.39825,   59.31917,    -0.55557,3.61333,6
   173.50156,   59.37417,    -0.55712,3.61136,6
   174.60544,   59.42916,    -0.55820,3.60938,6
   175.70933,   59.48417,    -0.55956,3.60739,6
   176.81321,   59.53917,    -0.56060,3.60538,6
   177.91700,   59.59417,    -0.56199,3.60335,6
   179.02102,   59.64917,    -0.56280,3.60132,6
   180.12438,   59.70417,    -0.56388,3.59927,6
   181.22757,   59.75917,    -0.56464,3.59720,6
   182.33093,   59.81417,    -0.56556,3.59513,6
   183.43403,   59.86917,    -0.56640,3.59304,6
   184.53744,   59.92417,    -0.56734,3.59093,6
   185.64051,   59.97917,    -0.56823,3.58881,6
   186.74313,   60.03417,    -0.56919,3.58668,6
   187.84587,   60.08917,    -0.57011,3.58453,6
   188.94925,   60.14417,    -0.57100,3.58237,6
   190.05315,   60.19917,    -0.57197,3.58020,6
   191.15733,   60.25417,    -0.57300,3.57801,6
   192.26154,   60.30917,    -0.57392,3.57581,6
   193.36556,   60.36417,    -0.57499,3.57359,6
   194.46882,   60.41917,    -0.57587,3.57136,6
   195.57190,   60.47417,    -0.57669,3.56912,6
   196.67520,   60.52917,    -0.57753,3.56687,6
   197.77823,   60.58417,    -0.57846,3.56460,6
   198.88128,   60.63917,    -0.57948,3.56231,6
   199.98477,   60.69417,    -0.58031,3.56002,6
   201.08816,   60.74917,    -0.58115,3.55771,6
   202.19143,   60.80416,    -0.58202,3.55539,6
   203.29510,   60.85917,    -0.58288,3.55305,6
   204.39875,   60.91417,    -0.58395,3.55070,6
   205.50193,   60.96917,    -0.58491,3.54834,6
   206.60488,   61.02417,    -0.58585,3.54596,6
   207.70793,   61.07917,    -0.58669,3.54357,6
   208.81115,   61.13417,    -0.58746,3.54117,6
   209.91416,   61.18917,    -0.58844,3.53875,6
   211.01733,   61.24417,    -0.58919,3.53633,6
   212.12033,   61.29917,    -0.58995,3.53388,6
   213.22284,   61.35417,    -0.59086,3.53143,6
   214.32559,   61.40917,    -0.59170,3.52896,6
   215.42812,   61.46417,    -0.59257,3.52648,6
   216.53056,   61.51917,    -0.59354,3.52399,6
   217.63330,   61.57417,    -0.59430,3.52149,6
   218.73626,   61.62917,    -0.59519,3.51897,6
   219.83979,   61.68417,    -0.59614,3.51643,6
   220.94343,   61.73917,    -0.59721,3.51389,6
   222.04672,   61.79417,    -0.59815,3.51133,6
   223.15025,   61.84917,    -0.59893,3.50875,6
   224.25357,   61.90417,    -0.59975,3.50617,6
   225.35675,   61.95917,    -0.60045,3.50357,6
   226.46003,   62.01417,    -0.60122,3.50096,6
   227.56328,   62.06917,    -0.60190,3.49834,6
   228.66693,   62.12417,    -0.60291,3.49570,6
   229.77052,   62.17916,    -0.60374,3.49305,6
   230.87338,   62.23417,    -0.60448,3.49039,6
   231.97620,   62.28917,    -0.60525,3.48772,6
   233.07884,   62.34417,    -0.60573,3.48504,6
   234.18148,   62.39917,    -0.60651,3.48234,6
   235.28425,   62.45417,    -0.60717,3.47963,6
   236.38718,   62.50917,    -0.60801,3.47691,6
   237.48987,   62.56417,    -0.60861,3.47417,6
   238.59241,   62.61917,    -0.60937,3.47142,6
   239.69557,   62.67417,    -0.61020,3.46866,6
   240.79893,   62.72917,    -0.61073,3.46589,6
   241.90261,   62.78417,    -0.61140,3.46310,6
   243.00626,   62.83917,    -0.61235,3.46031,6
   244.10921,   62.89417,    -0.61294,3.45750,6
   245.21203,   62.94917,    -0.61353,3.45467,6
   246.31546,   63.00417,    -0.61422,3.45184,6
   247.41913,   63.05917,    -0.61490,3.44899,6
   248.52248,   63.11417,    -0.61562,3.44613,6
   249.62561,   63.16917,    -0.61623,3.44326,6
   250.72856,   63.22417,    -0.61696,3.44038,6
   251.83130,   63.27917,    -0.61747,3.43749,6
   252.93393,   63.33417,    -0.61802,3.43458,6
   254.03630,   63.38917,    -0.61874,3.43166,6
   255.13859,   63.44417,    -0.61935,3.42874,7
   256.21276,   63.49917,    -0.62328,3.42587,7
   257.00783,   63.55416,    -0.62671,3.42374,7
   257.16053,   63.60917,    -0.56101,3.42333,7
   256.44841,   63.66417,    -0.36941,3.42524,7
   254.98012,   63.71917,-5.8972e-002,3.42916,7
   253.15976,   63.77417,     0.27580,3.43398,7
   251.29453,   63.82917,     0.52737,3.43890,7
   249.50029,   63.88417,     0.66917,3.44359,7
   247.80977,   63.93917,     0.73246,3.44798,7
   246.22447,   63.99417,     0.74530,3.45207,7
   244.73400,   64.04916,     0.72619,3.45590,7
   243.32029,   64.10416,     0.69588,3.45951,7
   241.96606,   64.15916,     0.66299,3.46294,7
   240.66076,   64.21416,     0.62920,3.46624,7
   239.40588,   64.26917,     0.60142,3.46939,7
   238.20035,   64.32417,     0.57456,3.47240,7
   237.03653,   64.37917,     0.54608,3.47530,7
   235.90706,   64.43417,     0.52306,3.47809,7
   234.79582,   64.48917,     0.50210,3.48083,7
   233.69123,   64.54417,     0.48466,3.48354,7
   232.58535,   64.59917,     0.47617,3.48624,7
   231.47218,   64.65417,     0.47056,3.48894,7
   230.35453,   64.70917,     0.46836,3.49165,7
   229.24006,   64.76417,     0.46964,3.49433,7
   228.13012,   64.81917,     0.46824,3.49699,7
   227.02329,   64.87417,     0.46540,3.49962,7
   225.91665,   64.92917,     0.46569,3.50225,7
   224.80118,   64.98417,     0.46372,3.50488,7
   223.67882,   65.03917,     0.46426,3.50752,7
   222.55777,   65.09417,     0.46874,3.51014,7
   221.43853,   65.14917,     0.46813,3.51274,7
   220.31865,   65.20417,     0.46755,3.51533,7
   219.19765,   65.25916,     0.46934,3.51791,7
   218.07383,   65.31416,     0.46835,3.52048,7
   216.94971,   65.36916,     0.46891,3.52304,7
   215.83259,   65.42416,     0.47077,3.52557,7
   214.71971,   65.47916,     0.46784,3.52808,7
   213.60682,   65.53416,     0.46580,3.53057,7
   212.48918,   65.58916,     0.46633,3.53306,7
   211.36959,   65.64417,     0.46539,3.53555,7
   210.25371,   65.69917,     0.46687,3.53801,7
   209.14812,   65.75417,     0.46706,3.54043,7
   208.04877,   65.80917,     0.46251,3.54283,7
   206.94988,   65.86417,     0.46074,3.54522,7
   205.84271,   65.91917,     0.45946,3.54760,7
   204.72729,   65.97417,     0.45906,3.55000,7
   203.61171,   66.02917,     0.46292,3.55238,7
   202.50171,   66.08417,     0.46432,3.55473,7
   201.39988,   66.13917,     0.46192,3.55705,7
   200.30177,   66.19417,     0.46086,3.55936,7
   199.19541,   66.24917,     0.45852,3.56166,7
   198.07847,   66.30417,     0.45823,3.56398,7
   196.96023,   66.35917,     0.46304,3.56628,7
   195.85023,   66.41417,     0.46404,3.56855,7
   194.75106,   66.46917,     0.46231,3.57079,7
   193.65971,   66.52417,     0.46042,3.57300,7
   192.56530,   66.57917,     0.45594,3.57520,7
   191.46094,   66.63416,     0.45441,3.57741,7
   190.35188,   66.68916,     0.45775,3.57961,7
   189.24253,   66.74416,     0.45870,3.58180,7
   188.13924,   66.79916,     0.45898,3.58396,7
   187.04147,   66.85416,     0.45911,3.58610,7
   185.93723,   66.90916,     0.45646,3.58824,7
   184.82800,   66.96416,     0.45703,3.59037,7
   183.71929,   67.01917,     0.45959,3.59249,7
   182.61782,   67.07417,     0.45872,3.59458,7
   181.51976,   67.12917,     0.45721,3.59666,7
   180.41200,   67.18417,     0.45648,3.59873,7
   179.29530,   67.23917,     0.45670,3.60081,7
   178.18024,   67.29417,     0.46013,3.60287,7
   177.07765,   67.34917,     0.46143,3.60489,7
   175.98570,   67.40417,     0.45806,3.60688,7
   174.89882,   67.45917,     0.45485,3.60885,7
   173.80476,   67.51417,     0.45172,3.61082,7
   172.69559,   67.56917,     0.45089,3.61280,7
   171.58571,   67.62417,     0.45514,3.61477,7
   170.48306,   67.67917,     0.45723,3.61671,7
   169.39141,   67.73417,     0.45522,3.61861,7
   168.30624,   67.78917,     0.45325,3.62050,7
   167.21135,   67.84417,     0.44955,3.62238,7
   166.10271,   67.89917,     0.44965,3.62427,7
   164.99282,   67.95417,     0.45427,3.62616,7
   163.89259,   68.00916,     0.45543,3.62801,7
   162.80117,   68.06416,     0.45366,3.62983,7
   161.71376,   68.11916,     0.45193,3.63163,7
   160.61529,   68.17416,     0.44884,3.63344,7
   159.50582,   68.22916,     0.44944,3.63525,7
   158.39647,   68.28416,     0.45361,3.63704,7
   157.29418,   68.33916,     0.45433,3.63881,7
   156.20129,   68.39417,     0.45335,3.64055,7
   155.10629,   68.44917,     0.45150,3.64228,7
   154.00247,   68.50417,     0.44971,3.64401,7
   152.89618,   68.55917,     0.45101,3.64573,7
   151.79535,   68.61417,     0.45306,3.64743,7
   150.69953,   68.66917,     0.45139,3.64910,7
   149.60059,   68.72417,     0.44955,3.65076,7
   148.49482,   68.77917,     0.45041,3.65242,7
   147.39065,   68.83417,     0.45081,3.65406,7
   146.29459,   68.88917,     0.45141,3.65568,7
   145.20118,   68.94417,     0.44970,3.65728,7
   144.09682,   68.99917,     0.44747,3.65888,7
   142.98935,   69.05417,     0.45002,3.66046,7
   141.88665,   69.10917,     0.45230,3.66203,7
   140.79547,   69.16417,     0.45103,3.66357,7
   139.70847,   69.21917,     0.44876,3.66508,7
   138.61194,   69.27417,     0.44648,3.66660,7
   137.50912,   69.32917,     0.44711,3.66811,7
   136.41000,   69.38416,     0.45015,3.66960,7
   135.31682,   69.43916,     0.44952,3.67106,7
   134.21647,   69.49416,     0.44714,3.67253,7
   133.10917,   69.54916,     0.44871,3.67398,7
   132.00341,   69.60416,     0.45017,3.67542,7
   130.90700,   69.65916,     0.45044,3.67683,7
   129.81541,   69.71416,     0.44880,3.67822,7
   128.71588,   69.76917,     0.44646,3.67961,7
   127.61335,   69.82417,     0.44690,3.68099,7
   126.51871,   69.87917,     0.44810,3.68234,7
   125.42835,   69.93417,     0.44608,3.68367,7
   124.33276,   69.98917,     0.44367,3.68499,7
   123.22853,   70.04417,     0.44452,3.68631,7
   122.12471,   70.09917,     0.44622,3.68761,7
   121.03000,   70.15417,     0.44687,3.68889,7
   119.93565,   70.20917,     0.44476,3.69015,7
   118.83253,   70.26417,     0.44329,3.69141,7
   117.72765,   70.31917,     0.44517,3.69265,7
   116.63100,   70.37417,     0.44648,3.69387,7
   115.53947,   70.42917,     0.44489,3.69507,7
   114.44000,   70.48417,     0.44214,3.69626,7
   113.33712,   70.53917,     0.44317,3.69744,7
   112.24153,   70.59417,     0.44432,3.69860,7
   111.15306,   70.64917,     0.44323,3.69974,7
   110.05953,   70.70417,     0.44007,3.70086,7
   108.95912,   70.75916,     0.43975,3.70198,7
   107.85965,   70.81416,     0.44155,3.70308,7
   106.76641,   70.86916,     0.44165,3.70416,7
   105.66976,   70.92416,     0.43967,3.70523,7
   104.56700,   70.97916,     0.43963,3.70629,7
   103.46623,   71.03416,     0.44108,3.70734,7
   102.37435,   71.08916,     0.44113,3.70836,7
   101.27865,   71.14417,     0.43897,3.70936,7
   100.17576,   71.19917,     0.43834,3.71036,7
    99.07647,   71.25417,     0.44002,3.71134,7
    97.98535,   71.30917,     0.43959,3.71230,7
    96.88876,   71.36417,     0.43706,3.71325,7
    95.78718,   71.41917,     0.43697,3.71419,7
    94.68918,   71.47417,     0.43833,3.71511,7
    93.59771,   71.52917,     0.43776,3.71600,7
    92.49971,   71.58417,     0.43557,3.71689,7
    91.39912,   71.63917,     0.43571,3.71777,7
    90.30371,   71.69417,     0.43676,3.71862,7
    89.21053,   71.74917,     0.43562,3.71946,7
    88.11147,   71.80417,     0.43396,3.72029,7
    87.01265,   71.85917,     0.43462,3.72110,7
    85.92071,   71.91417,     0.43487,3.72189,7
    84.82900,   71.96917,     0.43248,3.72267,7
    83.73082,   72.02417,     0.43150,3.72343,7
    82.63353,   72.07917,     0.43208,3.72418,7
    81.54265,   72.13416,     0.43171,3.72491,7
    80.44941,   72.18916,     0.42883,3.72563,7
    79.35412,   72.24416,     0.42749,3.72633,7
    78.26318,   72.29916,     0.42571,3.72702,7
    77.17553,   72.35416,     0.42088,3.72768,7
    76.08200,   72.40916,     0.41498,3.72834,7
    74.99041,   72.46416,     0.40960,3.72898,7
    73.90465,   72.51917,     0.40141,3.72960,7
    72.81735,   72.57417,     0.39142,3.73020,7
    71.72800,   72.62917,     0.38294,3.73080,7
    70.64547,   72.68417,     0.37456,3.73137,7
    69.56312,   72.73917,     0.36466,3.73193,7
    68.47453,   72.79417,     0.35650,3.73247,7
    67.38806,   72.84917,     0.35078,3.73300,7
    66.30388,   72.90417,     0.34461,3.73351,7
    65.21424,   72.95917,     0.33824,3.73401,7
    64.12165,   73.01417,     0.33499,3.73450,7
    63.03224,   73.06917,     0.33164,3.73497,7
    61.94159,   73.12417,     0.32734,3.73543,7
    60.84482,   73.17917,     0.32418,3.73587,7
    59.75112,   73.23417,     0.32305,3.73629,7
    58.65829,   73.28917,     0.31986,3.73670,7
    57.56059,   73.34417,     0.31733,3.73710,7
    56.46247,   73.39917,     0.31649,3.73748,7
    55.37006,   73.45417,     0.31434,3.73784,7
    54.27276,   73.50916,     0.31128,3.73819,7
    53.17235,   73.56416,     0.31053,3.73852,7
    52.07629,   73.61916,     0.30948,3.73884,7
    50.97829,   73.67416,     0.30697,3.73914,7
    49.87835,   73.72916,     0.30539,3.73942,7
    48.78076,   73.78416,     0.30495,3.73969,7
    47.68512,   73.83916,     0.30274,3.73995,7
    46.58541,   73.89417,     0.30090,3.74019,7
    45.48635,   73.94917,     0.30053,3.74041,7
    44.38994,   74.00417,     0.29888,3.74062,7
    43.29012,   74.05917,     0.29680,3.74081,7
    42.18953,   74.11417,     0.29612,3.74098,7
    41.09271,   74.16917,     0.29545,3.74114,7
    39.99465,   74.22417,     0.29306,3.74129,7
    38.89418,   74.27917,     0.29211,3.74142,7
    37.79700,   74.33417,     0.29144,3.74153,7
    36.70018,   74.38917,     0.28946,3.74163,7
    35.59924,   74.44417,     0.28810,3.74171,7
    34.50071,   74.49917,     0.28773,3.74177,7
    33.40435,   74.55417,     0.28613,3.74182,7
    32.30382,   74.60917,     0.28434,3.74186,7
    31.20412,   74.66417,     0.28394,3.74187,7
    30.10724,   74.71917,     0.28290,3.74188,7
    29.00641,   74.77417,     0.28085,3.74186,7
    27.90553,   74.82917,     0.28027,3.74183,7
    26.80876,   74.88416,     0.27955,3.74179,7
    25.84200,   74.93250,     0.27777,3.74174,7